Workbook

Sheet Overview
A1: Evidence · 研究回测底稿
A4: NVDA 近五年日线行情回顾与 AI 行业大事件研究（含 2025-01-27 下跌归因）
A6: 蓝色单元格为输入。Parameters 修改权重、成本与再平衡频率后，MonthlyCalc 与本页公式自动重算。ExecutionLedger 为原研究下一开盘成交快照，不随 Excel 参数更改。
A9: 所有价格来自有哈希的行情快照。月度估值采用不晚于股票收盘的可用日线；BTC 价格可能来自前一 UTC 日。宏观数据为当前历史版本，仅作事后解释。
A12: 研究版本 | B12: 15412514d7234a05
A13: 区间 | B13: 2021-09-28 / 2026-09-29
A16: 月度近似期末净资产 | B16: =MonthlyCalc!G61 -> 1068174.6
A17: 累计收益（含初始费用） | B17: =B16/Parameters!B2-1 -> 9.6817459
A18: 最大回撤 | B18: =MIN(MonthlyCalc!J2:J61) -> -0.62820621
A19: 公式 / Python 初始差额 | B19: =MAX(MonthlyCalc!M2:M61)-MIN(MonthlyCalc!M2:M61) -> 0
A21: 初始参数差额用于核对交付时默认参数。修改参数后差额变化是预期现象。Sources 与 EventWindows 保留原始链接和对应交易窗口。

Sheet Parameters
A1: 参数 | B1: 可修改数值 | C1: 口径 / 约束
A2: 初始资金 | B2: 100000 | C2: 美元
A3: 交易成本 bps | B3: 10 | C3: 0–100；只按成交额计费，GLD 管理费已体现在价格中
A4: 再平衡月数 | B4: 1 | C4: 0=持有；1=每月；3=每季；12=每年
A5: 权重合计 | B5: =SUM(B8:B8) -> 1 | C5: 必须为 100%
A6: 公式口径 | B6: 月度配置近似 | C6: 上期持仓获得下一期收益，在估值时点近似调仓；不等同于开盘执行台账
A8: NVDA | B8: 1

Sheet Daily
A1: Symbol | B1: Date | C1: Open | D1: High | E1: Low | F1: Close | G1: AdjClose | H1: Volume | I1: Opened UTC | J1: Closed UTC | K1: Dataset ID
A2: NVDA | B2: 2020-08-24 | C2: 12.88375 | D2: 12.9125 | E2: 12.5075 | F2: 12.72025 | G2: 12.647443 | H2: 490564000 | I2: 2020-08-24T13:30:00+00:00 | J2: 2020-08-24T20:00:00+00:00 | K2: prices-NVDA-e6d1853924e8
A3: NVDA | B3: 2020-08-25 | C3: 12.63075 | D3: 12.76125 | E3: 12.57375 | F3: 12.75 | G3: 12.677024 | H3: 289076000 | I3: 2020-08-25T13:30:00+00:00 | J3: 2020-08-25T20:00:00+00:00 | K3: prices-NVDA-e6d1853924e8
A4: NVDA | B4: 2020-08-26 | C4: 12.79925 | D4: 12.8685 | E4: 12.67775 | F4: 12.773 | G4: 12.699892 | H4: 321244000 | I4: 2020-08-26T13:30:00+00:00 | J4: 2020-08-26T20:00:00+00:00 | K4: prices-NVDA-e6d1853924e8
A5: NVDA | B5: 2020-08-27 | C5: 12.7815 | D5: 12.85 | E5: 12.5665 | F5: 12.62825 | G5: 12.555972 | H5: 317604000 | I5: 2020-08-27T13:30:00+00:00 | J5: 2020-08-27T20:00:00+00:00 | K5: prices-NVDA-e6d1853924e8
A6: NVDA | B6: 2020-08-28 | C6: 12.675 | D6: 13.148 | E6: 12.6425 | F6: 13.14775 | G6: 13.072497 | H6: 537160000 | I6: 2020-08-28T13:30:00+00:00 | J6: 2020-08-28T20:00:00+00:00 | K6: prices-NVDA-e6d1853924e8
A7: NVDA | B7: 2020-08-31 | C7: 13.18275 | D7: 13.575 | E7: 13.03775 | F7: 13.3745 | G7: 13.297948 | H7: 500840000 | I7: 2020-08-31T13:30:00+00:00 | J7: 2020-08-31T20:00:00+00:00 | K7: prices-NVDA-e6d1853924e8
A8: NVDA | B8: 2020-09-01 | C8: 13.48 | D8: 13.99375 | E8: 13.4365 | F8: 13.821 | G8: 13.746007 | H8: 511316000 | I8: 2020-09-01T13:30:00+00:00 | J8: 2020-09-01T20:00:00+00:00 | K8: prices-NVDA-e6d1853924e8
A9: NVDA | B9: 2020-09-02 | C9: 14.70375 | D9: 14.72675 | E9: 13.9 | F9: 14.3465 | G9: 14.268653 | H9: 874012000 | I9: 2020-09-02T13:30:00+00:00 | J9: 2020-09-02T20:00:00+00:00 | K9: prices-NVDA-e6d1853924e8
A10: NVDA | B10: 2020-09-03 | C10: 13.82875 | D10: 13.8845 | E10: 12.87875 | F10: 13.0155 | G10: 12.944875 | H10: 945128000 | I10: 2020-09-03T13:30:00+00:00 | J10: 2020-09-03T20:00:00+00:00 | K10: prices-NVDA-e6d1853924e8
A11: NVDA | B11: 2020-09-04 | C11: 12.78375 | D11: 13.175 | E11: 11.70475 | F11: 12.6225 | G11: 12.55401 | H11: 1463684000 | I11: 2020-09-04T13:30:00+00:00 | J11: 2020-09-04T20:00:00+00:00 | K11: prices-NVDA-e6d1853924e8
A12: NVDA | B12: 2020-09-08 | C12: 11.7345 | D12: 12.55 | E12: 11.70425 | F12: 11.913 | G12: 11.848358 | H12: 795728000 | I12: 2020-09-08T13:30:00+00:00 | J12: 2020-09-08T20:00:00+00:00 | K12: prices-NVDA-e6d1853924e8
A13: NVDA | B13: 2020-09-09 | C13: 12.4 | D13: 12.80925 | E13: 12.23175 | F13: 12.715 | G13: 12.646007 | H13: 736200000 | I13: 2020-09-09T13:30:00+00:00 | J13: 2020-09-09T20:00:00+00:00 | K13: prices-NVDA-e6d1853924e8
... A3063: SPY | B3063: 2026-09-28 | C3063: 768.34998 | D3063: 769.53998 | E3063: 763.71997 | F3063: 765.60999 | G3063: 765.60999 | H3063: 42296700 | I3063: 2026-09-28T13:30:00+00:00 | J3063: 2026-09-28T20:00:00+00:00 | K3063: prices-SPY-ba0266b147e1

Sheet Monthly
A1: 估值日期 | B1: 估值 UTC | C1: NVDA | D1: NVDA 实际日线
A2: 2021-09-30 | B2: 2021-09-30T20:00:00+00:00 | C2: =Daily!G280 -> 20.625158 | D2: 2021-09-30T20:00:00+00:00
A3: 2021-10-29 | B3: 2021-10-29T20:00:00+00:00 | C3: =Daily!G301 -> 25.45488 | D3: 2021-10-29T20:00:00+00:00
A4: 2021-11-30 | B4: 2021-11-30T21:00:00+00:00 | C4: =Daily!G322 -> 32.532696 | D4: 2021-11-30T21:00:00+00:00
A5: 2021-12-31 | B5: 2021-12-31T21:00:00+00:00 | C5: =Daily!G344 -> 29.28561 | D5: 2021-12-31T21:00:00+00:00
A6: 2022-01-31 | B6: 2022-01-31T21:00:00+00:00 | C6: =Daily!G364 -> 24.381605 | D6: 2022-01-31T21:00:00+00:00
A7: 2022-02-28 | B7: 2022-02-28T21:00:00+00:00 | C7: =Daily!G383 -> 24.281034 | D7: 2022-02-28T21:00:00+00:00
A8: 2022-03-31 | B8: 2022-03-31T20:00:00+00:00 | C8: =Daily!G406 -> 27.174299 | D8: 2022-03-31T20:00:00+00:00
A9: 2022-04-29 | B9: 2022-04-29T20:00:00+00:00 | C9: =Daily!G426 -> 18.471081 | D9: 2022-04-29T20:00:00+00:00
A10: 2022-05-31 | B10: 2022-05-31T20:00:00+00:00 | C10: =Daily!G447 -> 18.595566 | D10: 2022-05-31T20:00:00+00:00
A11: 2022-06-30 | B11: 2022-06-30T20:00:00+00:00 | C11: =Daily!G468 -> 15.100134 | D11: 2022-06-30T20:00:00+00:00
A12: 2022-07-29 | B12: 2022-07-29T20:00:00+00:00 | C12: =Daily!G488 -> 18.092468 | D12: 2022-07-29T20:00:00+00:00
A13: 2022-08-31 | B13: 2022-08-31T20:00:00+00:00 | C13: =Daily!G511 -> 15.03539 | D13: 2022-08-31T20:00:00+00:00
A14: 2022-09-30 | B14: 2022-09-30T20:00:00+00:00 | C14: =Daily!G532 -> 12.095454 | D14: 2022-09-30T20:00:00+00:00
A15: 2022-10-31 | B15: 2022-10-31T20:00:00+00:00 | C15: =Daily!G553 -> 13.448583 | D15: 2022-10-31T20:00:00+00:00
A16: 2022-11-30 | B16: 2022-11-30T21:00:00+00:00 | C16: =Daily!G574 -> 16.86661 | D16: 2022-11-30T21:00:00+00:00
A17: 2022-12-30 | B17: 2022-12-30T21:00:00+00:00 | C17: =Daily!G595 -> 14.565301 | D17: 2022-12-30T21:00:00+00:00
A18: 2023-01-31 | B18: 2023-01-31T21:00:00+00:00 | C18: =Daily!G615 -> 19.471899 | D18: 2023-01-31T21:00:00+00:00
A19: 2023-02-28 | B19: 2023-02-28T21:00:00+00:00 | C19: =Daily!G634 -> 23.138636 | D19: 2023-02-28T21:00:00+00:00
A20: 2023-03-31 | B20: 2023-03-31T20:00:00+00:00 | C20: =Daily!G657 -> 27.689142 | D20: 2023-03-31T20:00:00+00:00
A21: 2023-04-28 | B21: 2023-04-28T20:00:00+00:00 | C21: =Daily!G676 -> 27.661236 | D21: 2023-04-28T20:00:00+00:00
A22: 2023-05-31 | B22: 2023-05-31T20:00:00+00:00 | C22: =Daily!G698 -> 37.71434 | D22: 2023-05-31T20:00:00+00:00
A23: 2023-06-30 | B23: 2023-06-30T20:00:00+00:00 | C23: =Daily!G719 -> 42.172562 | D23: 2023-06-30T20:00:00+00:00
A24: 2023-07-31 | B24: 2023-07-31T20:00:00+00:00 | C24: =Daily!G739 -> 46.586021 | D24: 2023-07-31T20:00:00+00:00
A25: 2023-08-31 | B25: 2023-08-31T20:00:00+00:00 | C25: =Daily!G762 -> 49.203987 | D25: 2023-08-31T20:00:00+00:00
A26: 2023-09-29 | B26: 2023-09-29T20:00:00+00:00 | C26: =Daily!G782 -> 43.369469 | D26: 2023-09-29T20:00:00+00:00
A27: 2023-10-31 | B27: 2023-10-31T20:00:00+00:00 | C27: =Daily!G804 -> 40.658573 | D27: 2023-10-31T20:00:00+00:00
A28: 2023-11-30 | B28: 2023-11-30T21:00:00+00:00 | C28: =Daily!G825 -> 46.630737 | D28: 2023-11-30T21:00:00+00:00
A29: 2023-12-29 | B29: 2023-12-29T21:00:00+00:00 | C29: =Daily!G845 -> 49.378876 | D29: 2023-12-29T21:00:00+00:00
A30: 2024-01-31 | B30: 2024-01-31T21:00:00+00:00 | C30: =Daily!G866 -> 61.349186 | D30: 2024-01-31T21:00:00+00:00
A31: 2024-02-29 | B31: 2024-02-29T21:00:00+00:00 | C31: =Daily!G886 -> 78.883362 | D31: 2024-02-29T21:00:00+00:00
A32: 2024-03-28 | B32: 2024-03-28T20:00:00+00:00 | C32: =Daily!G906 -> 90.099091 | D32: 2024-03-28T20:00:00+00:00
A33: 2024-04-30 | B33: 2024-04-30T20:00:00+00:00 | C33: =Daily!G928 -> 86.156334 | D33: 2024-04-30T20:00:00+00:00
A34: 2024-05-31 | B34: 2024-05-31T20:00:00+00:00 | C34: =Daily!G950 -> 109.32128 | D34: 2024-05-31T20:00:00+00:00
A35: 2024-06-28 | B35: 2024-06-28T20:00:00+00:00 | C35: =Daily!G969 -> 123.19887 | D35: 2024-06-28T20:00:00+00:00
A36: 2024-07-31 | B36: 2024-07-31T20:00:00+00:00 | C36: =Daily!G991 -> 116.69685 | D36: 2024-07-31T20:00:00+00:00
A37: 2024-08-30 | B37: 2024-08-30T20:00:00+00:00 | C37: =Daily!G1013 -> 119.04037 | D37: 2024-08-30T20:00:00+00:00
A38: 2024-09-30 | B38: 2024-09-30T20:00:00+00:00 | C38: =Daily!G1033 -> 121.11502 | D38: 2024-09-30T20:00:00+00:00
A39: 2024-10-31 | B39: 2024-10-31T20:00:00+00:00 | C39: =Daily!G1056 -> 132.40474 | D39: 2024-10-31T20:00:00+00:00
A40: 2024-11-29 | B40: 2024-11-29T18:00:00+00:00 | C40: =Daily!G1076 -> 137.88005 | D40: 2024-11-29T18:00:00+00:00
...

Sheet MonthlyCalc
A1: 估值日期 | B1: NVDA 调仓前 | C1: 费用前资产 | D1: 再平衡 | E1: 成交额近似 | F1: 费用 | G1: 净资产 | H1: NVDA 调仓后 | I1: 历史峰值 | J1: 回撤 | K1: 期间收益 | L1: Python 初始校验 | M1: 初始参数差额
A2: =Monthly!A2 -> 2021-09-30 | B2: =Parameters!$B$2*Parameters!$B$8 -> 100000 | C2: =SUM(B2:B2) -> 100000 | D2: =TRUE() -> TRUE | E2: =C2 -> 100000 | F2: =IF(D2,E2*Parameters!$B$3/10000,0) -> 100 | G2: =IF(ABS(Parameters!$B$5-1)>0.00000001,NA(),C2-F2) -> 99900 | H2: =IF(D2,G2*Parameters!$B$8,B2) -> 99900 | I2: =MAX(Parameters!$B$2,G$2:G2) -> 100000 | J2: =G2/I2-1 -> -0.001 | K2: =G2/Parameters!$B$2-1 -> -0.001 | L2: 99900 | M2: =G2-L2 -> 0
A3: =Monthly!A3 -> 2021-10-29 | B3: =H2*Monthly!C3/Monthly!C2 -> 123293.23 | C3: =SUM(B3:B3) -> 123293.23 | D3: =IF(Parameters!$B$4=0,FALSE(),MOD(1,Parameters!$B$4)=0) -> TRUE | E3: =ABS(C3*Parameters!$B$8-B3) -> 0 | F3: =IF(D3,E3*Parameters!$B$3/10000,0) -> 0 | G3: =IF(ABS(Parameters!$B$5-1)>0.00000001,NA(),C3-F3) -> 123293.23 | H3: =IF(D3,G3*Parameters!$B$8,B3) -> 123293.23 | I3: =MAX(Parameters!$B$2,G$2:G3) -> 123293.23 | J3: =G3/I3-1 -> 0 | K3: =G3/G2-1 -> 0.23416652 | L3: 123293.23 | M3: =G3-L3 -> 0
A4: =Monthly!A4 -> 2021-11-30 | B4: =H3*Monthly!C4/Monthly!C3 -> 157575.34 | C4: =SUM(B4:B4) -> 157575.34 | D4: =IF(Parameters!$B$4=0,FALSE(),MOD(2,Parameters!$B$4)=0) -> TRUE | E4: =ABS(C4*Parameters!$B$8-B4) -> 0 | F4: =IF(D4,E4*Parameters!$B$3/10000,0) -> 0 | G4: =IF(ABS(Parameters!$B$5-1)>0.00000001,NA(),C4-F4) -> 157575.34 | H4: =IF(D4,G4*Parameters!$B$8,B4) -> 157575.34 | I4: =MAX(Parameters!$B$2,G$2:G4) -> 157575.34 | J4: =G4/I4-1 -> 0 | K4: =G4/G3-1 -> 0.27805341 | L4: 157575.34 | M4: =G4-L4 -> 0
A5: =Monthly!A5 -> 2021-12-31 | B5: =H4*Monthly!C5/Monthly!C4 -> 141847.76 | C5: =SUM(B5:B5) -> 141847.76 | D5: =IF(Parameters!$B$4=0,FALSE(),MOD(3,Parameters!$B$4)=0) -> TRUE | E5: =ABS(C5*Parameters!$B$8-B5) -> 0 | F5: =IF(D5,E5*Parameters!$B$3/10000,0) -> 0 | G5: =IF(ABS(Parameters!$B$5-1)>0.00000001,NA(),C5-F5) -> 141847.76 | H5: =IF(D5,G5*Parameters!$B$8,B5) -> 141847.76 | I5: =MAX(Parameters!$B$2,G$2:G5) -> 157575.34 | J5: =G5/I5-1 -> -0.099809914 | K5: =G5/G4-1 -> -0.099809914 | L5: 141847.76 | M5: =G5-L5 -> 0
A6: =Monthly!A6 -> 2022-01-31 | B6: =H5*Monthly!C6/Monthly!C5 -> 118094.72 | C6: =SUM(B6:B6) -> 118094.72 | D6: =IF(Parameters!$B$4=0,FALSE(),MOD(4,Parameters!$B$4)=0) -> TRUE | E6: =ABS(C6*Parameters!$B$8-B6) -> 0 | F6: =IF(D6,E6*Parameters!$B$3/10000,0) -> 0 | G6: =IF(ABS(Parameters!$B$5-1)>0.00000001,NA(),C6-F6) -> 118094.72 | H6: =IF(D6,G6*Parameters!$B$8,B6) -> 118094.72 | I6: =MAX(Parameters!$B$2,G$2:G6) -> 157575.34 | J6: =G6/I6-1 -> -0.25055073 | K6: =G6/G5-1 -> -0.16745443 | L6: 118094.72 | M6: =G6-L6 -> 0
A7: =Monthly!A7 -> 2022-02-28 | B7: =H6*Monthly!C7/Monthly!C6 -> 117607.6 | C7: =SUM(B7:B7) -> 117607.6 | D7: =IF(Parameters!$B$4=0,FALSE(),MOD(5,Parameters!$B$4)=0) -> TRUE | E7: =ABS(C7*Parameters!$B$8-B7) -> 0 | F7: =IF(D7,E7*Parameters!$B$3/10000,0) -> 0 | G7: =IF(ABS(Parameters!$B$5-1)>0.00000001,NA(),C7-F7) -> 117607.6 | H7: =IF(D7,G7*Parameters!$B$8,B7) -> 117607.6 | I7: =MAX(Parameters!$B$2,G$2:G7) -> 157575.34 | J7: =G7/I7-1 -> -0.2536421 | K7: =G7/G6-1 -> -0.0041248588 | L7: 117607.6 | M7: =G7-L7 -> 0
A8: =Monthly!A8 -> 2022-03-31 | B8: =H7*Monthly!C8/Monthly!C7 -> 131621.41 | C8: =SUM(B8:B8) -> 131621.41 | D8: =IF(Parameters!$B$4=0,FALSE(),MOD(6,Parameters!$B$4)=0) -> TRUE | E8: =ABS(C8*Parameters!$B$8-B8) -> 0 | F8: =IF(D8,E8*Parameters!$B$3/10000,0) -> 0 | G8: =IF(ABS(Parameters!$B$5-1)>0.00000001,NA(),C8-F8) -> 131621.41 | H8: =IF(D8,G8*Parameters!$B$8,B8) -> 131621.41 | I8: =MAX(Parameters!$B$2,G$2:G8) -> 157575.34 | J8: =G8/I8-1 -> -0.16470804 | K8: =G8/G7-1 -> 0.11915739 | L8: 131621.41 | M8: =G8-L8 -> 0
A9: =Monthly!A9 -> 2022-04-29 | B9: =H8*Monthly!C9/Monthly!C8 -> 89466.512 | C9: =SUM(B9:B9) -> 89466.512 | D9: =IF(Parameters!$B$4=0,FALSE(),MOD(7,Parameters!$B$4)=0) -> TRUE | E9: =ABS(C9*Parameters!$B$8-B9) -> 0 | F9: =IF(D9,E9*Parameters!$B$3/10000,0) -> 0 | G9: =IF(ABS(Parameters!$B$5-1)>0.00000001,NA(),C9-F9) -> 89466.512 | H9: =IF(D9,G9*Parameters!$B$8,B9) -> 89466.512 | I9: =MAX(Parameters!$B$2,G$2:G9) -> 157575.34 | J9: =G9/I9-1 -> -0.43223024 | K9: =G9/G8-1 -> -0.32027389 | L9: 89466.512 | M9: =G9-L9 -> 0
A10: =Monthly!A10 -> 2022-05-31 | B10: =H9*Monthly!C10/Monthly!C9 -> 90069.467 | C10: =SUM(B10:B10) -> 90069.467 | D10: =IF(Parameters!$B$4=0,FALSE(),MOD(8,Parameters!$B$4)=0) -> TRUE | E10: =ABS(C10*Parameters!$B$8-B10) -> 0 | F10: =IF(D10,E10*Parameters!$B$3/10000,0) -> 0 | G10: =IF(ABS(Parameters!$B$5-1)>0.00000001,NA(),C10-F10) -> 90069.467 | H10: =IF(D10,G10*Parameters!$B$8,B10) -> 90069.467 | I10: =MAX(Parameters!$B$2,G$2:G10) -> 157575.34 | J10: =G10/I10-1 -> -0.42840378 | K10: =G10/G9-1 -> 0.0067394549 | L10: 90069.467 | M10: =G10-L10 -> 0
A11: =Monthly!A11 -> 2022-06-30 | B11: =H10*Monthly!C11/Monthly!C10 -> 73138.996 | C11: =SUM(B11:B11) -> 73138.996 | D11: =IF(Parameters!$B$4=0,FALSE(),MOD(9,Parameters!$B$4)=0) -> TRUE | E11: =ABS(C11*Parameters!$B$8-B11) -> 0 | F11: =IF(D11,E11*Parameters!$B$3/10000,0) -> 0 | G11: =IF(ABS(Parameters!$B$5-1)>0.00000001,NA(),C11-F11) -> 73138.996 | H11: =IF(D11,G11*Parameters!$B$8,B11) -> 73138.996 | I11: =MAX(Parameters!$B$2,G$2:G11) -> 157575.34 | J11: =G11/I11-1 -> -0.53584744 | K11: =G11/G10-1 -> -0.18797126 | L11: 73138.996 | M11: =G11-L11 -> 0
A12: =Monthly!A12 -> 2022-07-29 | B12: =H11*Monthly!C12/Monthly!C11 -> 87632.665 | C12: =SUM(B12:B12) -> 87632.665 | D12: =IF(Parameters!$B$4=0,FALSE(),MOD(10,Parameters!$B$4)=0) -> TRUE | E12: =ABS(C12*Parameters!$B$8-B12) -> 0 | F12: =IF(D12,E12*Parameters!$B$3/10000,0) -> 0 | G12: =IF(ABS(Parameters!$B$5-1)>0.00000001,NA(),C12-F12) -> 87632.665 | H12: =IF(D12,G12*Parameters!$B$8,B12) -> 87632.665 | I12: =MAX(Parameters!$B$2,G$2:G12) -> 157575.34 | J12: =G12/I12-1 -> -0.44386815 | K12: =G12/G11-1 -> 0.19816608 | L12: 87632.665 | M12: =G12-L12 -> 0
A13: =Monthly!A13 -> 2022-08-31 | B13: =H12*Monthly!C13/Monthly!C12 -> 72825.402 | C13: =SUM(B13:B13) -> 72825.402 | D13: =IF(Parameters!$B$4=0,FALSE(),MOD(11,Parameters!$B$4)=0) -> TRUE | E13: =ABS(C13*Parameters!$B$8-B13) -> 0 | F13: =IF(D13,E13*Parameters!$B$3/10000,0) -> 0 | G13: =IF(ABS(Parameters!$B$5-1)>0.00000001,NA(),C13-F13) -> 72825.402 | H13: =IF(D13,G13*Parameters!$B$8,B13) -> 72825.402 | I13: =MAX(Parameters!$B$2,G$2:G13) -> 157575.34 | J13: =G13/I13-1 -> -0.53783756 | K13: =G13/G12-1 -> -0.16896967 | L13: 72825.402 | M13: =G13-L13 -> 0
A14: =Monthly!A14 -> 2022-09-30 | B14: =H13*Monthly!C14/Monthly!C13 -> 58585.532 | C14: =SUM(B14:B14) -> 58585.532 | D14: =IF(Parameters!$B$4=0,FALSE(),MOD(12,Parameters!$B$4)=0) -> TRUE | E14: =ABS(C14*Parameters!$B$8-B14) -> 0 | F14: =IF(D14,E14*Parameters!$B$3/10000,0) -> 0 | G14: =IF(ABS(Parameters!$B$5-1)>0.00000001,NA(),C14-F14) -> 58585.532 | H14: =IF(D14,G14*Parameters!$B$8,B14) -> 58585.532 | I14: =MAX(Parameters!$B$2,G$2:G14) -> 157575.34 | J14: =G14/I14-1 -> -0.62820621 | K14: =G14/G13-1 -> -0.19553438 | L14: 58585.532 | M14: =G14-L14 -> 0
A15: =Monthly!A15 -> 2022-10-31 | B15: =H14*Monthly!C15/Monthly!C14 -> 65139.544 | C15: =SUM(B15:B15) -> 65139.544 | D15: =IF(Parameters!$B$4=0,FALSE(),MOD(13,Parameters!$B$4)=0) -> TRUE | E15: =ABS(C15*Parameters!$B$8-B15) -> 0 | F15: =IF(D15,E15*Parameters!$B$3/10000,0) -> 0 | G15: =IF(ABS(Parameters!$B$5-1)>0.00000001,NA(),C15-F15) -> 65139.544 | H15: =IF(D15,G15*Parameters!$B$8,B15) -> 65139.544 | I15: =MAX(Parameters!$B$2,G$2:G15) -> 157575.34 | J15: =G15/I15-1 -> -0.58661333 | K15: =G15/G14-1 -> 0.11187082 | L15: 65139.544 | M15: =G15-L15 -> 0
A16: =Monthly!A16 -> 2022-11-30 | B16: =H15*Monthly!C16/Monthly!C15 -> 81695.096 | C16: =SUM(B16:B16) -> 81695.096 | D16: =IF(Parameters!$B$4=0,FALSE(),MOD(14,Parameters!$B$4)=0) -> TRUE | E16: =ABS(C16*Parameters!$B$8-B16) -> 0 | F16: =IF(D16,E16*Parameters!$B$3/10000,0) -> 0 | G16: =IF(ABS(Parameters!$B$5-1)>0.00000001,NA(),C16-F16) -> 81695.096 | H16: =IF(D16,G16*Parameters!$B$8,B16) -> 81695.096 | I16: =MAX(Parameters!$B$2,G$2:G16) -> 157575.34 | J16: =G16/I16-1 -> -0.48154897 | K16: =G16/G15-1 -> 0.25415518 | L16: 81695.096 | M16: =G16-L16 -> 0
A17: =Monthly!A17 -> 2022-12-30 | B17: =H16*Monthly!C17/Monthly!C16 -> 70548.48 | C17: =SUM(B17:B17) -> 70548.48 | D17: =IF(Parameters!$B$4=0,FALSE(),MOD(15,Parameters!$B$4)=0) -> TRUE | E17: =ABS(C17*Parameters!$B$8-B17) -> 0 | F17: =IF(D17,E17*Parameters!$B$3/10000,0) -> 0 | G17: =IF(ABS(Parameters!$B$5-1)>0.00000001,NA(),C17-F17) -> 70548.48 | H17: =IF(D17,G17*Parameters!$B$8,B17) -> 70548.48 | I17: =MAX(Parameters!$B$2,G$2:G17) -> 157575.34 | J17: =G17/I17-1 -> -0.5522873 | K17: =G17/G16-1 -> -0.13644169 | L17: 70548.48 | M17: =G17-L17 -> 0
A18: =Monthly!A18 -> 2023-01-31 | B18: =H17*Monthly!C18/Monthly!C17 -> 94314.074 | C18: =SUM(B18:B18) -> 94314.074 | D18: =IF(Parameters!$B$4=0,FALSE(),MOD(16,Parameters!$B$4)=0) -> TRUE | E18: =ABS(C18*Parameters!$B$8-B18) -> 0 | F18: =IF(D18,E18*Parameters!$B$3/10000,0) -> 0 | G18: =IF(ABS(Parameters!$B$5-1)>0.00000001,NA(),C18-F18) -> 94314.074 | H18: =IF(D18,G18*Parameters!$B$8,B18) -> 94314.074 | I18: =MAX(Parameters!$B$2,G$2:G18) -> 157575.34 | J18: =G18/I18-1 -> -0.40146678 | K18: =G18/G17-1 -> 0.33686898 | L18: 94314.074 | M18: =G18-L18 -> 0
A19: =Monthly!A19 -> 2023-02-28 | B19: =H18*Monthly!C19/Monthly!C18 -> 112074.28 | C19: =SUM(B19:B19) -> 112074.28 | D19: =IF(Parameters!$B$4=0,FALSE(),MOD(17,Parameters!$B$4)=0) -> TRUE | E19: =ABS(C19*Parameters!$B$8-B19) -> 0 | F19: =IF(D19,E19*Parameters!$B$3/10000,0) -> 0 | G19: =IF(ABS(Parameters!$B$5-1)>0.00000001,NA(),C19-F19) -> 112074.28 | H19: =IF(D19,G19*Parameters!$B$8,B19) -> 112074.28 | I19: =MAX(Parameters!$B$2,G$2:G19) -> 157575.34 | J19: =G19/I19-1 -> -0.28875751 | K19: =G19/G18-1 -> 0.18830914 | L19: 112074.28 | M19: =G19-L19 -> 0
A20: =Monthly!A20 -> 2023-03-31 | B20: =H19*Monthly!C20/Monthly!C19 -> 134115.11 | C20: =SUM(B20:B20) -> 134115.11 | D20: =IF(Parameters!$B$4=0,FALSE(),MOD(18,Parameters!$B$4)=0) -> TRUE | E20: =ABS(C20*Parameters!$B$8-B20) -> 0 | F20: =IF(D20,E20*Parameters!$B$3/10000,0) -> 0 | G20: =IF(ABS(Parameters!$B$5-1)>0.00000001,NA(),C20-F20) -> 134115.11 | H20: =IF(D20,G20*Parameters!$B$8,B20) -> 134115.11 | I20: =MAX(Parameters!$B$2,G$2:G20) -> 157575.34 | J20: =G20/I20-1 -> -0.14888264 | K20: =G20/G19-1 -> 0.1966627 | L20: 134115.11 | M20: =G20-L20 -> 0
A21: =Monthly!A21 -> 2023-04-28 | B21: =H20*Monthly!C21/Monthly!C20 -> 133979.94 | C21: =SUM(B21:B21) -> 133979.94 | D21: =IF(Parameters!$B$4=0,FALSE(),MOD(19,Parameters!$B$4)=0) -> TRUE | E21: =ABS(C21*Parameters!$B$8-B21) -> 0 | F21: =IF(D21,E21*Parameters!$B$3/10000,0) -> 0 | G21: =IF(ABS(Parameters!$B$5-1)>0.00000001,NA(),C21-F21) -> 133979.94 | H21: =IF(D21,G21*Parameters!$B$8,B21) -> 133979.94 | I21: =MAX(Parameters!$B$2,G$2:G21) -> 157575.34 | J21: =G21/I21-1 -> -0.14974043 | K21: =G21/G20-1 -> -0.001007847 | L21: 133979.94 | M21: =G21-L21 -> 0
A22: =Monthly!A22 -> 2023-05-31 | B22: =H21*Monthly!C22/Monthly!C21 -> 182673.15 | C22: =SUM(B22:B22) -> 182673.15 | D22: =IF(Parameters!$B$4=0,FALSE(),MOD(20,Parameters!$B$4)=0) -> TRUE | E22: =ABS(C22*Parameters!$B$8-B22) -> 0 | F22: =IF(D22,E22*Parameters!$B$3/10000,0) -> 0 | G22: =IF(ABS(Parameters!$B$5-1)>0.00000001,NA(),C22-F22) -> 182673.15 | H22: =IF(D22,G22*Parameters!$B$8,B22) -> 182673.15 | I22: =MAX(Parameters!$B$2,G$2:G22) -> 182673.15 | J22: =G22/I22-1 -> 0 | K22: =G22/G21-1 -> 0.36343656 | L22: 182673.15 | M22: =G22-L22 -> 0
A23: =Monthly!A23 -> 2023-06-30 | B23: =H22*Monthly!C23/Monthly!C22 -> 204266.99 | C23: =SUM(B23:B23) -> 204266.99 | D23: =IF(Parameters!$B$4=0,FALSE(),MOD(21,Parameters!$B$4)=0) -> TRUE | E23: =ABS(C23*Parameters!$B$8-B23) -> 0 | F23: =IF(D23,E23*Parameters!$B$3/10000,0) -> 0 | G23: =IF(ABS(Parameters!$B$5-1)>0.00000001,NA(),C23-F23) -> 204266.99 | H23: =IF(D23,G23*Parameters!$B$8,B23) -> 204266.99 | I23: =MAX(Parameters!$B$2,G$2:G23) -> 204266.99 | J23: =G23/I23-1 -> 0 | K23: =G23/G22-1 -> 0.11821025 | L23: 204266.99 | M23: =G23-L23 -> 0
A24: =Monthly!A24 -> 2023-07-31 | B24: =H23*Monthly!C24/Monthly!C23 -> 225644.02 | C24: =SUM(B24:B24) -> 225644.02 | D24: =IF(Parameters!$B$4=0,FALSE(),MOD(22,Parameters!$B$4)=0) -> TRUE | E24: =ABS(C24*Parameters!$B$8-B24) -> 0 | F24: =IF(D24,E24*Parameters!$B$3/10000,0) -> 0 | G24: =IF(ABS(Parameters!$B$5-1)>0.00000001,NA(),C24-F24) -> 225644.02 | H24: =IF(D24,G24*Parameters!$B$8,B24) -> 225644.02 | I24: =MAX(Parameters!$B$2,G$2:G24) -> 225644.02 | J24: =G24/I24-1 -> 0 | K24: =G24/G23-1 -> 0.1046524 | L24: 225644.02 | M24: =G24-L24 -> 0
A25: =Monthly!A25 -> 2023-08-31 | B25: =H24*Monthly!C25/Monthly!C24 -> 238324.39 | C25: =SUM(B25:B25) -> 238324.39 | D25: =IF(Parameters!$B$4=0,FALSE(),MOD(23,Parameters!$B$4)=0) -> TRUE | E25: =ABS(C25*Parameters!$B$8-B25) -> 0 | F25: =IF(D25,E25*Parameters!$B$3/10000,0) -> 0 | G25: =IF(ABS(Parameters!$B$5-1)>0.00000001,NA(),C25-F25) -> 238324.39 | H25: =IF(D25,G25*Parameters!$B$8,B25) -> 238324.39 | I25: =MAX(Parameters!$B$2,G$2:G25) -> 238324.39 | J25: =G25/I25-1 -> 0 | K25: =G25/G24-1 -> 0.056196379 | L25: 238324.39 | M25: =G25-L25 -> 0
A26: =Monthly!A26 -> 2023-09-29 | B26: =H25*Monthly!C26/Monthly!C25 -> 210064.32 | C26: =SUM(B26:B26) -> 210064.32 | D26: =IF(Parameters!$B$4=0,FALSE(),MOD(24,Parameters!$B$4)=0) -> TRUE | E26: =ABS(C26*Parameters!$B$8-B26) -> 0 | F26: =IF(D26,E26*Parameters!$B$3/10000,0) -> 0 | G26: =IF(ABS(Parameters!$B$5-1)>0.00000001,NA(),C26-F26) -> 210064.32 | H26: =IF(D26,G26*Parameters!$B$8,B26) -> 210064.32 | I26: =MAX(Parameters!$B$2,G$2:G26) -> 238324.39 | J26: =G26/I26-1 -> -0.11857816 | K26: =G26/G25-1 -> -0.11857816 | L26: 210064.32 | M26: =G26-L26 -> 0
A27: =Monthly!A27 -> 2023-10-31 | B27: =H26*Monthly!C27/Monthly!C26 -> 196933.83 | C27: =SUM(B27:B27) -> 196933.83 | D27: =IF(Parameters!$B$4=0,FALSE(),MOD(25,Parameters!$B$4)=0) -> TRUE | E27: =ABS(C27*Parameters!$B$8-B27) -> 0 | F27: =IF(D27,E27*Parameters!$B$3/10000,0) -> 0 | G27: =IF(ABS(Parameters!$B$5-1)>0.00000001,NA(),C27-F27) -> 196933.83 | H27: =IF(D27,G27*Parameters!$B$8,B27) -> 196933.83 | I27: =MAX(Parameters!$B$2,G$2:G27) -> 238324.39 | J27: =G27/I27-1 -> -0.1736732 | K27: =G27/G26-1 -> -0.062507004 | L27: 196933.83 | M27: =G27-L27 -> 0
A28: =Monthly!A28 -> 2023-11-30 | B28: =H27*Monthly!C28/Monthly!C27 -> 225860.6 | C28: =SUM(B28:B28) -> 225860.6 | D28: =IF(Parameters!$B$4=0,FALSE(),MOD(26,Parameters!$B$4)=0) -> TRUE | E28: =ABS(C28*Parameters!$B$8-B28) -> 0 | F28: =IF(D28,E28*Parameters!$B$3/10000,0) -> 0 | G28: =IF(ABS(Parameters!$B$5-1)>0.00000001,NA(),C28-F28) -> 225860.6 | H28: =IF(D28,G28*Parameters!$B$8,B28) -> 225860.6 | I28: =MAX(Parameters!$B$2,G$2:G28) -> 238324.39 | J28: =G28/I28-1 -> -0.052297587 | K28: =G28/G27-1 -> 0.14688573 | L28: 225860.6 | M28: =G28-L28 -> 0
A29: =Monthly!A29 -> 2023-12-29 | B29: =H28*Monthly!C29/Monthly!C28 -> 239171.48 | C29: =SUM(B29:B29) -> 239171.48 | D29: =IF(Parameters!$B$4=0,FALSE(),MOD(27,Parameters!$B$4)=0) -> TRUE | E29: =ABS(C29*Parameters!$B$8-B29) -> 0 | F29: =IF(D29,E29*Parameters!$B$3/10000,0) -> 0 | G29: =IF(ABS(Parameters!$B$5-1)>0.00000001,NA(),C29-F29) -> 239171.48 | H29: =IF(D29,G29*Parameters!$B$8,B29) -> 239171.48 | I29: =MAX(Parameters!$B$2,G$2:G29) -> 239171.48 | J29: =G29/I29-1 -> 0 | K29: =G29/G28-1 -> 0.058934055 | L29: 239171.48 | M29: =G29-L29 -> 0
A30: =Monthly!A30 -> 2024-01-31 | B30: =H29*Monthly!C30/Monthly!C29 -> 297150.87 | C30: =SUM(B30:B30) -> 297150.87 | D30: =IF(Parameters!$B$4=0,FALSE(),MOD(28,Parameters!$B$4)=0) -> TRUE | E30: =ABS(C30*Parameters!$B$8-B30) -> 0 | F30: =IF(D30,E30*Parameters!$B$3/10000,0) -> 0 | G30: =IF(ABS(Parameters!$B$5-1)>0.00000001,NA(),C30-F30) -> 297150.87 | H30: =IF(D30,G30*Parameters!$B$8,B30) -> 297150.87 | I30: =MAX(Parameters!$B$2,G$2:G30) -> 297150.87 | J30: =G30/I30-1 -> 0 | K30: =G30/G29-1 -> 0.24241763 | L30: 297150.87 | M30: =G30-L30 -> 0
A31: =Monthly!A31 -> 2024-02-29 | B31: =H30*Monthly!C31/Monthly!C30 -> 382079.39 | C31: =SUM(B31:B31) -> 382079.39 | D31: =IF(Parameters!$B$4=0,FALSE(),MOD(29,Parameters!$B$4)=0) -> TRUE | E31: =ABS(C31*Parameters!$B$8-B31) -> 0 | F31: =IF(D31,E31*Parameters!$B$3/10000,0) -> 0 | G31: =IF(ABS(Parameters!$B$5-1)>0.00000001,NA(),C31-F31) -> 382079.39 | H31: =IF(D31,G31*Parameters!$B$8,B31) -> 382079.39 | I31: =MAX(Parameters!$B$2,G$2:G31) -> 382079.39 | J31: =G31/I31-1 -> 0 | K31: =G31/G30-1 -> 0.28580943 | L31: 382079.39 | M31: =G31-L31 -> 0
A32: =Monthly!A32 -> 2024-03-28 | B32: =H31*Monthly!C32/Monthly!C31 -> 436403.88 | C32: =SUM(B32:B32) -> 436403.88 | D32: =IF(Parameters!$B$4=0,FALSE(),MOD(30,Parameters!$B$4)=0) -> TRUE | E32: =ABS(C32*Parameters!$B$8-B32) -> 0 | F32: =IF(D32,E32*Parameters!$B$3/10000,0) -> 0 | G32: =IF(ABS(Parameters!$B$5-1)>0.00000001,NA(),C32-F32) -> 436403.88 | H32: =IF(D32,G32*Parameters!$B$8,B32) -> 436403.88 | I32: =MAX(Parameters!$B$2,G$2:G32) -> 436403.88 | J32: =G32/I32-1 -> 0 | K32: =G32/G31-1 -> 0.14218117 | L32: 436403.88 | M32: =G32-L32 -> 0
A33: =Monthly!A33 -> 2024-04-30 | B33: =H32*Monthly!C33/Monthly!C32 -> 417306.75 | C33: =SUM(B33:B33) -> 417306.75 | D33: =IF(Parameters!$B$4=0,FALSE(),MOD(31,Parameters!$B$4)=0) -> TRUE | E33: =ABS(C33*Parameters!$B$8-B33) -> 0 | F33: =IF(D33,E33*Parameters!$B$3/10000,0) -> 0 | G33: =IF(ABS(Parameters!$B$5-1)>0.00000001,NA(),C33-F33) -> 417306.75 | H33: =IF(D33,G33*Parameters!$B$8,B33) -> 417306.75 | I33: =MAX(Parameters!$B$2,G$2:G33) -> 436403.88 | J33: =G33/I33-1 -> -0.043760227 | K33: =G33/G32-1 -> -0.043760227 | L33: 417306.75 | M33: =G33-L33 -> 0
A34: =Monthly!A34 -> 2024-05-31 | B34: =H33*Monthly!C34/Monthly!C33 -> 529508.47 | C34: =SUM(B34:B34) -> 529508.47 | D34: =IF(Parameters!$B$4=0,FALSE(),MOD(32,Parameters!$B$4)=0) -> TRUE | E34: =ABS(C34*Parameters!$B$8-B34) -> 0 | F34: =IF(D34,E34*Parameters!$B$3/10000,0) -> 0 | G34: =IF(ABS(Parameters!$B$5-1)>0.00000001,NA(),C34-F34) -> 529508.47 | H34: =IF(D34,G34*Parameters!$B$8,B34) -> 529508.47 | I34: =MAX(Parameters!$B$2,G$2:G34) -> 529508.47 | J34: =G34/I34-1 -> 0 | K34: =G34/G33-1 -> 0.26887109 | L34: 529508.47 | M34: =G34-L34 -> 0
A35: =Monthly!A35 -> 2024-06-28 | B35: =H34*Monthly!C35/Monthly!C34 -> 596725.94 | C35: =SUM(B35:B35) -> 596725.94 | D35: =IF(Parameters!$B$4=0,FALSE(),MOD(33,Parameters!$B$4)=0) -> TRUE | E35: =ABS(C35*Parameters!$B$8-B35) -> 0 | F35: =IF(D35,E35*Parameters!$B$3/10000,0) -> 0 | G35: =IF(ABS(Parameters!$B$5-1)>0.00000001,NA(),C35-F35) -> 596725.94 | H35: =IF(D35,G35*Parameters!$B$8,B35) -> 596725.94 | I35: =MAX(Parameters!$B$2,G$2:G35) -> 596725.94 | J35: =G35/I35-1 -> 0 | K35: =G35/G34-1 -> 0.12694314 | L35: 596725.94 | M35: =G35-L35 -> 0
A36: =Monthly!A36 -> 2024-07-31 | B36: =H35*Monthly!C36/Monthly!C35 -> 565232.79 | C36: =SUM(B36:B36) -> 565232.79 | D36: =IF(Parameters!$B$4=0,FALSE(),MOD(34,Parameters!$B$4)=0) -> TRUE | E36: =ABS(C36*Parameters!$B$8-B36) -> 0 | F36: =IF(D36,E36*Parameters!$B$3/10000,0) -> 0 | G36: =IF(ABS(Parameters!$B$5-1)>0.00000001,NA(),C36-F36) -> 565232.79 | H36: =IF(D36,G36*Parameters!$B$8,B36) -> 565232.79 | I36: =MAX(Parameters!$B$2,G$2:G36) -> 596725.94 | J36: =G36/I36-1 -> -0.052776574 | K36: =G36/G35-1 -> -0.052776574 | L36: 565232.79 | M36: =G36-L36 -> 0
A37: =Monthly!A37 -> 2024-08-30 | B37: =H36*Monthly!C37/Monthly!C36 -> 576583.83 | C37: =SUM(B37:B37) -> 576583.83 | D37: =IF(Parameters!$B$4=0,FALSE(),MOD(35,Parameters!$B$4)=0) -> TRUE | E37: =ABS(C37*Parameters!$B$8-B37) -> 0 | F37: =IF(D37,E37*Parameters!$B$3/10000,0) -> 0 | G37: =IF(ABS(Parameters!$B$5-1)>0.00000001,NA(),C37-F37) -> 576583.83 | H37: =IF(D37,G37*Parameters!$B$8,B37) -> 576583.83 | I37: =MAX(Parameters!$B$2,G$2:G37) -> 596725.94 | J37: =G37/I37-1 -> -0.033754374 | K37: =G37/G36-1 -> 0.020082062 | L37: 576583.83 | M37: =G37-L37 -> 0
A38: =Monthly!A38 -> 2024-09-30 | B38: =H37*Monthly!C38/Monthly!C37 -> 586632.62 | C38: =SUM(B38:B38) -> 586632.62 | D38: =IF(Parameters!$B$4=0,FALSE(),MOD(36,Parameters!$B$4)=0) -> TRUE | E38: =ABS(C38*Parameters!$B$8-B38) -> 0 | F38: =IF(D38,E38*Parameters!$B$3/10000,0) -> 0 | G38: =IF(ABS(Parameters!$B$5-1)>0.00000001,NA(),C38-F38) -> 586632.62 | H38: =IF(D38,G38*Parameters!$B$8,B38) -> 586632.62 | I38: =MAX(Parameters!$B$2,G$2:G38) -> 596725.94 | J38: =G38/I38-1 -> -0.016914498 | K38: =G38/G37-1 -> 0.017428152 | L38: 586632.62 | M38: =G38-L38 -> 0
A39: =Monthly!A39 -> 2024-10-31 | B39: =H38*Monthly!C39/Monthly!C38 -> 641315.49 | C39: =SUM(B39:B39) -> 641315.49 | D39: =IF(Parameters!$B$4=0,FALSE(),MOD(37,Parameters!$B$4)=0) -> TRUE | E39: =ABS(C39*Parameters!$B$8-B39) -> 0 | F39: =IF(D39,E39*Parameters!$B$3/10000,0) -> 0 | G39: =IF(ABS(Parameters!$B$5-1)>0.00000001,NA(),C39-F39) -> 641315.49 | H39: =IF(D39,G39*Parameters!$B$8,B39) -> 641315.49 | I39: =MAX(Parameters!$B$2,G$2:G39) -> 641315.49 | J39: =G39/I39-1 -> 0 | K39: =G39/G38-1 -> 0.093214851 | L39: 641315.49 | M39: =G39-L39 -> 0
A40: =Monthly!A40 -> 2024-11-29 | B40: =H39*Monthly!C40/Monthly!C39 -> 667835.7 | C40: =SUM(B40:B40) -> 667835.7 | D40: =IF(Parameters!$B$4=0,FALSE(),MOD(38,Parameters!$B$4)=0) -> TRUE | E40: =ABS(C40*Parameters!$B$8-B40) -> 0 | F40: =IF(D40,E40*Parameters!$B$3/10000,0) -> 0 | G40: =IF(ABS(Parameters!$B$5-1)>0.00000001,NA(),C40-F40) -> 667835.7 | H40: =IF(D40,G40*Parameters!$B$8,B40) -> 667835.7 | I40: =MAX(Parameters!$B$2,G$2:G40) -> 667835.7 | J40: =G40/I40-1 -> 0 | K40: =G40/G39-1 -> 0.041352835 | L40: 667835.7 | M40: =G40-L40 -> 0
...

Sheet ExecutionLedger
A1: Symbol | B1: Signal UTC | C1: Execution UTC | D1: Adjusted units | E1: Adjusted open | F1: Notional | G1: Cost | H1: Cash after

Sheet EventWindows
A1: Event ID | B1: 事件 | C1: 来源日期 | D1: 对齐交易日 | E1: Symbol | F1: Window | G1: Return | H1: Benchmark | I1: Relative | J1: Strength | K1: Confidence | L1: Source IDs | M1: 说明 | N1: Window start UTC | O1: Window end UTC
A2: ev-chatgpt-release-2022-11-30 | B2: OpenAI 向公众发布 ChatGPT | C2: 2022-11-30 | D2: 2022-11-30 | E2: NVDA | F2: 1 | G2: 0.082379306 | H2: 0.031500528 | I2: 0.050878779 | J2: 低 | K2: medium | L2: src-0574c1fd7cebfb | M2: 该来源为 HISTORY 网站的事后回顾条目（2025 年发布），事件日期由正文明确给出，非原始公告页。事后报道按原文支持的事件日期展示，不代表当时已公开或可交易的信号。 事后报道按原文支持的事件日期展示，不代表当时已公开或可交易的信号。 来源只有日期，盘前/盘后时间不确定；使用当日或下一交易日近似。 | N2: 2022-11-29T21:00:00+00:00 | O2: 2022-11-30T21:00:00+00:00
A3: ev-chatgpt-release-2022-11-30 | B3: OpenAI 向公众发布 ChatGPT | C3: 2022-11-30 | D3: 2022-11-30 | E3: NVDA | F3: 5 | G3: 0.02251354 | H3: -0.0035425285 | I3: 0.026056068 | J3: 低 | K3: medium | L3: src-0574c1fd7cebfb | M3: 该来源为 HISTORY 网站的事后回顾条目（2025 年发布），事件日期由正文明确给出，非原始公告页。事后报道按原文支持的事件日期展示，不代表当时已公开或可交易的信号。 事后报道按原文支持的事件日期展示，不代表当时已公开或可交易的信号。 来源只有日期，盘前/盘后时间不确定；使用当日或下一交易日近似。 | N3: 2022-11-29T21:00:00+00:00 | O3: 2022-12-06T21:00:00+00:00
A4: ev-chatgpt-release-2022-11-30 | B4: OpenAI 向公众发布 ChatGPT | C4: 2022-11-30 | D4: 2022-11-30 | E4: NVDA | F4: 20 | G4: -0.10227061 | H4: -0.042608989 | I4: -0.059661618 | J4: 低 | K4: medium | L4: src-0574c1fd7cebfb | M4: 该来源为 HISTORY 网站的事后回顾条目（2025 年发布），事件日期由正文明确给出，非原始公告页。事后报道按原文支持的事件日期展示，不代表当时已公开或可交易的信号。 事后报道按原文支持的事件日期展示，不代表当时已公开或可交易的信号。 来源只有日期，盘前/盘后时间不确定；使用当日或下一交易日近似。 | N4: 2022-11-29T21:00:00+00:00 | O4: 2022-12-28T21:00:00+00:00
A5: ev-nvda-q1fy24-earnings-2023-05-24 | B5: 英伟达 FY2024 一季度业绩与超预期指引，盘后股价大涨 26% | C5: 2023-05-24 | D5: 2023-05-25 | E5: NVDA | F5: 1 | G5: 0.24369611 | H5: 0.0086600524 | I5: 0.23503606 | J5: 高 | K5: high | L5: src-5d57f2e27d95e2, src-bb4a66fc5d1b12 | M5: 26% 涨幅为盘后（extended trading）表现，非收盘价。 | N5: 2023-05-24T20:00:00+00:00 | O5: 2023-05-25T20:00:00+00:00
A6: ev-nvda-q1fy24-earnings-2023-05-24 | B6: 英伟达 FY2024 一季度业绩与超预期指引，盘后股价大涨 26% | C6: 2023-05-24 | D6: 2023-05-25 | E6: NVDA | F6: 5 | G6: 0.30231178 | H6: 0.026101576 | I6: 0.27621021 | J6: 高 | K6: high | L6: src-5d57f2e27d95e2, src-bb4a66fc5d1b12 | M6: 26% 涨幅为盘后（extended trading）表现，非收盘价。 | N6: 2023-05-24T20:00:00+00:00 | O6: 2023-06-01T20:00:00+00:00
A7: ev-nvda-q1fy24-earnings-2023-05-24 | B7: 英伟达 FY2024 一季度业绩与超预期指引，盘后股价大涨 26% | C7: 2023-05-24 | D7: 2023-05-25 | E7: NVDA | F7: 20 | G7: 0.3823226 | H7: 0.057722905 | I7: 0.3245997 | J7: 高 | K7: high | L7: src-5d57f2e27d95e2, src-bb4a66fc5d1b12 | M7: 26% 涨幅为盘后（extended trading）表现，非收盘价。 | N7: 2023-05-24T20:00:00+00:00 | O7: 2023-06-23T20:00:00+00:00
A8: ev-blackwell-platform-2024-03-18 | B8: 英伟达在 GTC 发布 Blackwell 平台与 B200 GPU | C8: 2024-03-18 | D8: 2024-03-19 | E8: NVDA | F8: 1 | G8: 0.010660747 | H8: 0.0055571661 | I8: 0.0051035807 | J8: 低 | K8: high | L8: src-119d026375f8f1, src-2703b6b30f807b | M8: The Verge 报道为发布当日现场报道，含 3 月 19 日关于单卡价格 3 万至 4 万美元的更新段；英伟达官方新闻稿发布元数据为 2024-03-18。 | N8: 2024-03-18T20:00:00+00:00 | O8: 2024-03-19T20:00:00+00:00
A9: ev-blackwell-platform-2024-03-18 | B9: 英伟达在 GTC 发布 Blackwell 平台与 B200 GPU | C9: 2024-03-18 | D9: 2024-03-19 | E9: NVDA | F9: 5 | G9: 0.074014987 | H9: 0.013473457 | I9: 0.06054153 | J9: 低 | K9: high | L9: src-119d026375f8f1, src-2703b6b30f807b | M9: The Verge 报道为发布当日现场报道，含 3 月 19 日关于单卡价格 3 万至 4 万美元的更新段；英伟达官方新闻稿发布元数据为 2024-03-18。 | N9: 2024-03-18T20:00:00+00:00 | O9: 2024-03-25T20:00:00+00:00
A10: ev-blackwell-platform-2024-03-18 | B10: 英伟达在 GTC 发布 Blackwell 平台与 B200 GPU | C10: 2024-03-18 | D10: 2024-03-19 | E10: NVDA | F10: 20 | G10: -0.01175745 | H10: -0.018192073 | I10: 0.0064346231 | J10: 低 | K10: high | L10: src-119d026375f8f1, src-2703b6b30f807b | M10: The Verge 报道为发布当日现场报道，含 3 月 19 日关于单卡价格 3 万至 4 万美元的更新段；英伟达官方新闻稿发布元数据为 2024-03-18。 | N10: 2024-03-18T20:00:00+00:00 | O10: 2024-04-16T20:00:00+00:00
A11: ev-deepseek-r1-paper-2025-01-22 | B11: DeepSeek-R1 技术论文提交至 arXiv（v1） | C11: 2025-01-22 | D11: 2025-01-22 | E11: NVDA | F11: 1 | G11: 0.04430892 | H11: 0.0056213593 | I11: 0.03868756 | J11: 中 | K11: medium | L11: src-92838b9f7ab276 | M11: 该日期为论文 v1 提交日（submission history），不等同于模型权重或 API 的对外发布日；v2 于 2026 年 1 月 4 日修订。 来源只有日期，盘前/盘后时间不确定；使用当日或下一交易日近似。 同期存在其他已收录事件，无法分离各自作用。 | N11: 2025-01-21T21:00:00+00:00 | O11: 2025-01-22T21:00:00+00:00
A12: ev-deepseek-r1-paper-2025-01-22 | B12: DeepSeek-R1 技术论文提交至 arXiv（v1） | C12: 2025-01-22 | D12: 2025-01-22 | E12: NVDA | F12: 5 | G12: -0.084072884 | H12: 0.0024376664 | I12: -0.08651055 | J12: 中 | K12: medium | L12: src-92838b9f7ab276 | M12: 该日期为论文 v1 提交日（submission history），不等同于模型权重或 API 的对外发布日；v2 于 2026 年 1 月 4 日修订。 来源只有日期，盘前/盘后时间不确定；使用当日或下一交易日近似。 同期存在其他已收录事件，无法分离各自作用。 | N12: 2025-01-21T21:00:00+00:00 | O12: 2025-01-28T21:00:00+00:00
A13: ev-deepseek-r1-paper-2025-01-22 | B13: DeepSeek-R1 技术论文提交至 arXiv（v1） | C13: 2025-01-22 | D13: 2025-01-22 | E13: NVDA | F13: 20 | G13: -0.011361195 | H13: 0.01638348 | I13: -0.027744674 | J13: 中 | K13: medium | L13: src-92838b9f7ab276 | M13: 该日期为论文 v1 提交日（submission history），不等同于模型权重或 API 的对外发布日；v2 于 2026 年 1 月 4 日修订。 来源只有日期，盘前/盘后时间不确定；使用当日或下一交易日近似。 同期存在其他已收录事件，无法分离各自作用。 | N13: 2025-01-21T21:00:00+00:00 | O13: 2025-02-19T21:00:00+00:00
... A22: ev-nvda-q2fy27-earnings-2026-08-26 | B22: 英伟达 FY2027 二季度业绩超预期，指引强劲并披露 AWS 200 万 GPU 协议 | C22: 2026-08-26 | D22: 2026-08-26 | E22: NVDA | F22: 20 | G22: 0.059668288 | H22: 0.004970128 | I22: 0.05469816 | J22: 低 | K22: high | L22: src-095b03880c506c | M22: 该页为实时博客，含盘后多个更新时段；事件日期采用页面发布元数据（美东 8 月 26 日）。 日线包含公告前交易，无法精确隔离盘中反应。 | N22: 2026-08-25T20:00:00+00:00 | O22: 2026-09-23T20:00:00+00:00

Sheet Sources
A1: ID | B1: Title | C1: Original URL | D1: Retrieved UTC | E1: SHA-256 | F1: Status
A2: src-0b0ee9231d33b5 | B2: GitHub - deepseek-ai/DeepSeek-R1 · GitHub | C2: https://github.com/deepseek-ai/DeepSeek-R1 | D2: 2026-09-29T03:38:59.859568+00:00 | E2: d595c0ef5aa515a2614b15ceef5dac1596c7705d5069a31a61e20cdc750d22de | F2: retrieved
A3: src-35526d9a0fa829 | B3: DeepSeek-R1 Release | DeepSeek API Docs | C3: https://api-docs.deepseek.com/news/news250120/ | D3: 2026-09-29T03:39:00.640761+00:00 | E3: 8de25d7cc5df634345c1090b3429b41a05eaa0add9cfa311bbd368da70b9ab1b | F3: retrieved
A4: src-119d026375f8f1 | B4: Nvidia reveals Blackwell B200 GPU, the ‘world’s most powerful chip’ for AI | The Verge | C4: https://www.theverge.com/2024/3/18/24105157/nvidia-blackwell-gpu-b200-ai | D4: 2026-09-29T03:39:06.673137+00:00 | E4: 175c6c781faf9ba273fc65e80019100364eab7dc52fb585335adf6f117323d02 | F4: retrieved
A5: src-af915ec3e82793 | B5: Nvidia calls China’s DeepSeek R1 model ‘an excellent AI advancement’ | C5: https://www.cnbc.com/2025/01/27/nvidia-calls-chinas-deepseek-r1-model-an-excellent-ai-advancement.html | D5: 2026-09-29T03:39:07.708017+00:00 | E5: 37c2a2efe5f53c4f8d5f8810984f105e940ad6f6b85c842b47f1c2613aa7ebee | F5: retrieved
A6: src-5d57f2e27d95e2 | B6: Nvidia (NVDA) earnings report Q1 2024 | C6: https://www.cnbc.com/2023/05/24/nvidia-nvda-earnings-report-q1-2024.html | D6: 2026-09-29T03:39:13.295897+00:00 | E6: b31d35ae75c828f2061e67eb2915796d1056ba435ae1b7f3fd091fa57e004a24 | F6: retrieved
A7: src-b3f5e5db326593 | B7: Trump administration backs off Nvidia H20 chip crackdown : NPR | C7: https://www.npr.org/2025/04/09/nx-s1-5356480/nvidia-china-ai-h20-chips-trump | D7: 2026-09-29T03:39:39.772518+00:00 | E7: e4eab1251fd563185f4c8fbb70e492c13ef1f08af1e7e0958a622b569bcbf24f | F7: retrieved
A8: src-095b03880c506c | B8: Nvidia (NVDA) Q2 2027 earnings report: Live updates | C8: https://www.cnbc.com/2026/08/26/nvidia-nvda-earnings-report-q2-2027-live-updates.html | D8: 2026-09-29T03:39:43.123914+00:00 | E8: 73ccadaad6c2d8a2ea0ef8c678a4e39e2944d85e4582cc8f9cb95b0d088ee637 | F8: retrieved
A9: src-bb4a66fc5d1b12 | B9: NVIDIA Corporation - NVIDIA Announces Financial Results for First Quarter Fiscal 2024 | C9: https://investor.nvidia.com/news/press-release-details/2023/NVIDIA-Announces-Financial-Results-for-First-Quarter-Fiscal-2024/default.aspx | D9: 2026-09-29T03:39:46.872618+00:00 | E9: 4cf80fb589e6e73a4502573b9556a4ad78c150b82419b67ba53603d74a3507ca | F9: retrieved
A10: src-0574c1fd7cebfb | B10: ChatGPT is released to the public | HISTORY | C10: https://www.history.com/this-day-in-history/november-30/chatgpt-released-openai | D10: 2026-09-29T03:39:52.366702+00:00 | E10: 51c71d151be465359df223ccb0a59dfd9688087af6ddeb44262f532045a729bd | F10: retrieved
A11: src-92838b9f7ab276 | B11: [2501.12948] DeepSeek-R1: Incentivizing Reasoning Capability in LLMs via Reinforcement Learning | C11: https://arxiv.org/abs/2501.12948 | D11: 2026-09-29T06:26:09.498802+00:00 | E11: 3d23c9bbfad76a7c05fe3c62c8332e885fd46c3cc02b50b227eb362e1f1b4293 | F11: retrieved
A12: src-2703b6b30f807b | B12: NVIDIA Blackwell Platform Arrives to Power a New Era of Computing | NVIDIA Newsroom | C12: https://nvidianews.nvidia.com/news/nvidia-blackwell-platform-arrives-to-power-a-new-era-of-computing | D12: 2026-09-29T06:26:14.871640+00:00 | E12: 9478aba3b300065d3911668cdcd230bf3e91b9e9febcd36b215de452f655f790 | F12: retrieved
... A20: prices-SPY-ba0266b147e1 | B20: SPY | C20: https://query1.finance.yahoo.com/v8/finance/chart/SPY?period1=1598227200&period2=1790726400&interval=1d&events=div%2Csplits&includeAdjustedClose=true | D20: 2026-09-29T02:33:25.620138+00:00 | E20: ba0266b147e1210651f9991e41f1ed135bc89c7cc3faa0088be1865d09d2bbb6 | F20: Yahoo split-adjusted OHLC; adj_close additionally reflects distributions

Sheet Macro
A1: Series | B1: Observation date | C1: Value | D1: Vintage use

Sheet Coverage
A1: 检查项 | B1: 状态 | C1: 依据 / 缺口
A2: 研究要求覆盖 | B2: 通过 | C2: 覆盖检查与事实核验分别执行；相关不代表因果
A3: ChatGPT 发布 | B3: covered | C3: ev-chatgpt-release-2022-11-30
A4: Blackwell 平台发布 | B4: covered | C4: ev-blackwell-platform-2024-03-18
A5: DeepSeek 相关事件 | B5: covered | C5: ev-deepseek-r1-paper-2025-01-22
A6: 2025-01-27 NVDA 下跌事件（区分论文日、模型发布日与市场反应日） | B6: covered | C6: ev-nvda-deepseek-selloff-2025-01-27

Sheet Associations
A1: 异动日期 | B1: 资产 | C1: 事件 ID | D1: 滞后日线数 | E1: 关联类型 | F1: 依据 | G1: 来源 ID
A2: 2023-05-25 | B2: NVDA | C2: ev-nvda-q1fy24-earnings-2023-05-24 | D2: 0 | E2: same_session_candidate | F2: 来源支持的事件公开后第 0 根日线出现变化；同标的与时间先后支持候选关联，未证明该事件触发行情。 | G2: src-5d57f2e27d95e2, src-bb4a66fc5d1b12
A3: 2025-01-27 | B3: NVDA | C3: ev-nvda-deepseek-selloff-2025-01-27 | D3: 0 | E3: retrospective_report | F3: 事后报道记录该日事件或市场反应，仅用于解释复核，不是当时可用的交易信号，也不构成因果证明。 | G3: src-af915ec3e82793
A4: 2025-01-27 | B4: NVDA | C4: ev-deepseek-r1-paper-2025-01-22 | D4: 3 | E4: delayed_candidate | F4: 来源支持的事件公开后第 3 根日线出现变化；同标的与时间先后支持候选关联，未证明该事件触发行情。 | G4: src-92838b9f7ab276
A5: 2025-04-09 | B5: NVDA | C5: ev-nvda-h20-policy-2025-04-09 | D5: 0 | E5: retrospective_report | F5: 事后报道记录该日事件或市场反应，仅用于解释复核，不是当时可用的交易信号，也不构成因果证明。 | G5: src-b3f5e5db326593
A6: 2026-08-27 | B6: NVDA | C6: ev-nvda-q2fy27-earnings-2026-08-26 | D6: 1 | E6: delayed_candidate | F6: 来源支持的事件公开后第 1 根日线出现变化；同标的与时间先后支持候选关联，未证明该事件触发行情。 | G6: src-095b03880c506c
