Workbook

Sheet Overview
A1: Evidence · 研究回测底稿
A4: 黄金 ETF 代理（GLD）与比特币（BTC-USD）近五年避险与抗通胀表现比较：60/40 组合、季度再平衡
A6: 蓝色单元格为输入。Parameters 修改权重、成本与再平衡频率后，MonthlyCalc 与本页公式自动重算。ExecutionLedger 为原研究下一开盘成交快照，不随 Excel 参数更改。
A9: 所有价格来自有哈希的行情快照。月度估值采用不晚于股票收盘的可用日线；BTC 价格可能来自前一 UTC 日。宏观数据为当前历史版本，仅作事后解释。
A12: 研究版本 | B12: 3302715305fc4dac
A13: 区间 | B13: 2021-09-28 / 2026-09-29
A16: 月度近似期末净资产 | B16: =MonthlyCalc!H61 -> 271732.73
A17: 累计收益（含初始费用） | B17: =B16/Parameters!B2-1 -> 1.7173273
A18: 最大回撤 | B18: =MIN(MonthlyCalc!L2:L61) -> -0.37446202
A19: 公式 / Python 初始差额 | B19: =MAX(MonthlyCalc!O2:O61)-MIN(MonthlyCalc!O2:O61) -> 0
A21: 初始参数差额用于核对交付时默认参数。修改参数后差额变化是预期现象。Sources 与 EventWindows 保留原始链接和对应交易窗口。
A26: GLD（SPDR Gold Shares）由实物黄金支持，目标是反映扣除信托费用后的金价表现。它于 2004 年上市，在 NYSE Arca 以美元交易，参考 LBMA Gold Price PM。采用 GLD 是因为其黄金敞口明确、交易历史较长，并具有可复核的美元行情，适合构建可投资代理的比较与回测。
A28: ETF 价格与现货金价存在费用、跟踪及交易时段差异。官方披露费用率为 0.40%（2026-09-28 核验）；历史价格已体现基金费用，回测只另计指定交易成本，避免重复扣费。
A30: GLD 官方产品说明

Sheet Parameters
A1: 参数 | B1: 可修改数值 | C1: 口径 / 约束
A2: 初始资金 | B2: 100000 | C2: 美元
A3: 交易成本 bps | B3: 20 | C3: 0–100；只按成交额计费，GLD 管理费已体现在价格中
A4: 再平衡月数 | B4: 3 | C4: 0=持有；1=每月；3=每季；12=每年
A5: 权重合计 | B5: =SUM(B8:B9) -> 1 | C5: 必须为 100%
A6: 公式口径 | B6: 月度配置近似 | C6: 上期持仓获得下一期收益，在估值时点近似调仓；不等同于开盘执行台账
A8: GLD | B8: 0.6
A9: BTC-USD | B9: 0.4

Sheet Daily
A1: Symbol | B1: Date | C1: Open | D1: High | E1: Low | F1: Close | G1: AdjClose | H1: Volume | I1: Opened UTC | J1: Closed UTC | K1: Dataset ID
A2: GLD | B2: 2020-08-24 | C2: 182.91 | D2: 182.92999 | E2: 180.69 | F2: 181 | G2: 181 | H2: 11605800 | I2: 2020-08-24T13:30:00+00:00 | J2: 2020-08-24T20:00:00+00:00 | K2: prices-GLD-1a8f833cf4e3
A3: GLD | B3: 2020-08-25 | C3: 181.06 | D3: 181.25 | E3: 179.73 | F3: 181.22 | G3: 181.22 | H3: 10056100 | I3: 2020-08-25T13:30:00+00:00 | J3: 2020-08-25T20:00:00+00:00 | K3: prices-GLD-1a8f833cf4e3
A4: GLD | B4: 2020-08-26 | C4: 180.25999 | D4: 183.58 | E4: 180.2 | F4: 183.36 | G4: 183.36 | H4: 12715800 | I4: 2020-08-26T13:30:00+00:00 | J4: 2020-08-26T20:00:00+00:00 | K4: prices-GLD-1a8f833cf4e3
A5: GLD | B5: 2020-08-27 | C5: 185 | D5: 185.17 | E5: 179.37 | F5: 181.24001 | G5: 181.24001 | H5: 16299200 | I5: 2020-08-27T13:30:00+00:00 | J5: 2020-08-27T20:00:00+00:00 | K5: prices-GLD-1a8f833cf4e3
A6: GLD | B6: 2020-08-28 | C6: 183.98 | D6: 185.39999 | E6: 183.39999 | F6: 184.39 | G6: 184.39 | H6: 13200800 | I6: 2020-08-28T13:30:00+00:00 | J6: 2020-08-28T20:00:00+00:00 | K6: prices-GLD-1a8f833cf4e3
A7: GLD | B7: 2020-08-31 | C7: 184.78999 | D7: 185.53 | E7: 184.28 | F7: 184.83 | G7: 184.83 | H7: 10251200 | I7: 2020-08-31T13:30:00+00:00 | J7: 2020-08-31T20:00:00+00:00 | K7: prices-GLD-1a8f833cf4e3
A8: GLD | B8: 2020-09-01 | C8: 186.99001 | D8: 186.99001 | E8: 184.33 | F8: 185.05 | G8: 185.05 | H8: 10662100 | I8: 2020-09-01T13:30:00+00:00 | J8: 2020-09-01T20:00:00+00:00 | K8: prices-GLD-1a8f833cf4e3
A9: GLD | B9: 2020-09-02 | C9: 183.75 | D9: 183.86 | E9: 181.5 | F9: 182.62 | G9: 182.62 | H9: 11536900 | I9: 2020-09-02T13:30:00+00:00 | J9: 2020-09-02T20:00:00+00:00 | K9: prices-GLD-1a8f833cf4e3
A10: GLD | B10: 2020-09-03 | C10: 182.3 | D10: 182.82001 | E10: 180.49001 | F10: 181.14 | G10: 181.14 | H10: 12148100 | I10: 2020-09-03T13:30:00+00:00 | J10: 2020-09-03T20:00:00+00:00 | K10: prices-GLD-1a8f833cf4e3
A11: GLD | B11: 2020-09-04 | C11: 180.95 | D11: 182.10001 | E11: 180.05 | F11: 181.64 | G11: 181.64 | H11: 11567900 | I11: 2020-09-04T13:30:00+00:00 | J11: 2020-09-04T20:00:00+00:00 | K11: prices-GLD-1a8f833cf4e3
A12: GLD | B12: 2020-09-08 | C12: 179.5 | D12: 182.27 | E12: 179.02 | F12: 181.28999 | G12: 181.28999 | H12: 13229200 | I12: 2020-09-08T13:30:00+00:00 | J12: 2020-09-08T20:00:00+00:00 | K12: prices-GLD-1a8f833cf4e3
A13: GLD | B13: 2020-09-09 | C13: 182.5 | D13: 183.22 | E13: 182.19 | F13: 183.05 | G13: 183.05 | H13: 8424100 | I13: 2020-09-09T13:30:00+00:00 | J13: 2020-09-09T20:00:00+00:00 | K13: prices-GLD-1a8f833cf4e3
... A5289: SPY | B5289: 2026-09-28 | C5289: 768.34998 | D5289: 769.53998 | E5289: 763.71997 | F5289: 765.60999 | G5289: 765.60999 | H5289: 42296700 | I5289: 2026-09-28T13:30:00+00:00 | J5289: 2026-09-28T20:00:00+00:00 | K5289: prices-SPY-ba0266b147e1

Sheet Monthly
A1: 估值日期 | B1: 估值 UTC | C1: GLD | D1: BTC-USD | E1: GLD 实际日线 | F1: BTC-USD 实际日线
A2: 2021-09-30 | B2: 2021-09-30T20:00:00+00:00 | C2: =Daily!G280 -> 164.22 | D2: =Daily!G1934 -> 41564.363 | E2: 2021-09-30T20:00:00+00:00 | F2: 2021-09-30T00:00:00+00:00
A3: 2021-10-29 | B3: 2021-10-29T20:00:00+00:00 | C3: =Daily!G301 -> 166.64999 | D3: =Daily!G1963 -> 60622.137 | E3: 2021-10-29T20:00:00+00:00 | F3: 2021-10-29T00:00:00+00:00
A4: 2021-11-30 | B4: 2021-11-30T21:00:00+00:00 | C4: =Daily!G322 -> 165.5 | D4: =Daily!G1995 -> 57806.566 | E4: 2021-11-30T21:00:00+00:00 | F4: 2021-11-30T00:00:00+00:00
A5: 2021-12-31 | B5: 2021-12-31T21:00:00+00:00 | C5: =Daily!G344 -> 170.96001 | D5: =Daily!G2026 -> 47178.125 | E5: 2021-12-31T21:00:00+00:00 | F5: 2021-12-31T00:00:00+00:00
A6: 2022-01-31 | B6: 2022-01-31T21:00:00+00:00 | C6: =Daily!G364 -> 168.09 | D6: =Daily!G2057 -> 37917.602 | E6: 2022-01-31T21:00:00+00:00 | F6: 2022-01-31T00:00:00+00:00
A7: 2022-02-28 | B7: 2022-02-28T21:00:00+00:00 | C7: =Daily!G383 -> 178.38 | D7: =Daily!G2085 -> 37709.785 | E7: 2022-02-28T21:00:00+00:00 | F7: 2022-02-28T00:00:00+00:00
A8: 2022-03-31 | B8: 2022-03-31T20:00:00+00:00 | C8: =Daily!G406 -> 180.64999 | D8: =Daily!G2116 -> 47062.664 | E8: 2022-03-31T20:00:00+00:00 | F8: 2022-03-31T00:00:00+00:00
A9: 2022-04-29 | B9: 2022-04-29T20:00:00+00:00 | C9: =Daily!G426 -> 176.91 | D9: =Daily!G2145 -> 39773.828 | E9: 2022-04-29T20:00:00+00:00 | F9: 2022-04-29T00:00:00+00:00
A10: 2022-05-31 | B10: 2022-05-31T20:00:00+00:00 | C10: =Daily!G447 -> 171.14 | D10: =Daily!G2177 -> 31726.391 | E10: 2022-05-31T20:00:00+00:00 | F10: 2022-05-31T00:00:00+00:00
A11: 2022-06-30 | B11: 2022-06-30T20:00:00+00:00 | C11: =Daily!G468 -> 168.46001 | D11: =Daily!G2207 -> 20104.023 | E11: 2022-06-30T20:00:00+00:00 | F11: 2022-06-30T00:00:00+00:00
A12: 2022-07-29 | B12: 2022-07-29T20:00:00+00:00 | C12: =Daily!G488 -> 164.10001 | D12: =Daily!G2236 -> 23843.887 | E12: 2022-07-29T20:00:00+00:00 | F12: 2022-07-29T00:00:00+00:00
A13: 2022-08-31 | B13: 2022-08-31T20:00:00+00:00 | C13: =Daily!G511 -> 159.27 | D13: =Daily!G2269 -> 19796.809 | E13: 2022-08-31T20:00:00+00:00 | F13: 2022-08-31T00:00:00+00:00
A14: 2022-09-30 | B14: 2022-09-30T20:00:00+00:00 | C14: =Daily!G532 -> 154.67 | D14: =Daily!G2299 -> 19573.051 | E14: 2022-09-30T20:00:00+00:00 | F14: 2022-09-30T00:00:00+00:00
A15: 2022-10-31 | B15: 2022-10-31T20:00:00+00:00 | C15: =Daily!G553 -> 151.91 | D15: =Daily!G2330 -> 20635.604 | E15: 2022-10-31T20:00:00+00:00 | F15: 2022-10-31T00:00:00+00:00
A16: 2022-11-30 | B16: 2022-11-30T21:00:00+00:00 | C16: =Daily!G574 -> 164.81 | D16: =Daily!G2360 -> 16444.982 | E16: 2022-11-30T21:00:00+00:00 | F16: 2022-11-30T00:00:00+00:00
A17: 2022-12-30 | B17: 2022-12-30T21:00:00+00:00 | C17: =Daily!G595 -> 169.64 | D17: =Daily!G2390 -> 16642.342 | E17: 2022-12-30T21:00:00+00:00 | F17: 2022-12-30T00:00:00+00:00
A18: 2023-01-31 | B18: 2023-01-31T21:00:00+00:00 | C18: =Daily!G615 -> 179.41 | D18: =Daily!G2422 -> 22840.139 | E18: 2023-01-31T21:00:00+00:00 | F18: 2023-01-31T00:00:00+00:00
A19: 2023-02-28 | B19: 2023-02-28T21:00:00+00:00 | C19: =Daily!G634 -> 169.78 | D19: =Daily!G2450 -> 23522.871 | E19: 2023-02-28T21:00:00+00:00 | F19: 2023-02-28T00:00:00+00:00
A20: 2023-03-31 | B20: 2023-03-31T20:00:00+00:00 | C20: =Daily!G657 -> 183.22 | D20: =Daily!G2481 -> 28033.562 | E20: 2023-03-31T20:00:00+00:00 | F20: 2023-03-31T00:00:00+00:00
A21: 2023-04-28 | B21: 2023-04-28T20:00:00+00:00 | C21: =Daily!G676 -> 184.8 | D21: =Daily!G2509 -> 29473.787 | E21: 2023-04-28T20:00:00+00:00 | F21: 2023-04-28T00:00:00+00:00
A22: 2023-05-31 | B22: 2023-05-31T20:00:00+00:00 | C22: =Daily!G698 -> 182.32001 | D22: =Daily!G2542 -> 27702.35 | E22: 2023-05-31T20:00:00+00:00 | F22: 2023-05-31T00:00:00+00:00
A23: 2023-06-30 | B23: 2023-06-30T20:00:00+00:00 | C23: =Daily!G719 -> 178.27 | D23: =Daily!G2572 -> 30445.352 | E23: 2023-06-30T20:00:00+00:00 | F23: 2023-06-30T00:00:00+00:00
A24: 2023-07-31 | B24: 2023-07-31T20:00:00+00:00 | C24: =Daily!G739 -> 182.35001 | D24: =Daily!G2603 -> 29275.309 | E24: 2023-07-31T20:00:00+00:00 | F24: 2023-07-31T00:00:00+00:00
A25: 2023-08-31 | B25: 2023-08-31T20:00:00+00:00 | C25: =Daily!G762 -> 180.02 | D25: =Daily!G2634 -> 27297.266 | E25: 2023-08-31T20:00:00+00:00 | F25: 2023-08-31T00:00:00+00:00
A26: 2023-09-29 | B26: 2023-09-29T20:00:00+00:00 | C26: =Daily!G782 -> 171.45 | D26: =Daily!G2663 -> 27021.547 | E26: 2023-09-29T20:00:00+00:00 | F26: 2023-09-29T00:00:00+00:00
A27: 2023-10-31 | B27: 2023-10-31T20:00:00+00:00 | C27: =Daily!G804 -> 184.09 | D27: =Daily!G2695 -> 34502.363 | E27: 2023-10-31T20:00:00+00:00 | F27: 2023-10-31T00:00:00+00:00
A28: 2023-11-30 | B28: 2023-11-30T21:00:00+00:00 | C28: =Daily!G825 -> 188.75 | D28: =Daily!G2725 -> 37858.492 | E28: 2023-11-30T21:00:00+00:00 | F28: 2023-11-30T00:00:00+00:00
A29: 2023-12-29 | B29: 2023-12-29T21:00:00+00:00 | C29: =Daily!G845 -> 191.17 | D29: =Daily!G2754 -> 42627.855 | E29: 2023-12-29T21:00:00+00:00 | F29: 2023-12-29T00:00:00+00:00
A30: 2024-01-31 | B30: 2024-01-31T21:00:00+00:00 | C30: =Daily!G866 -> 188.45 | D30: =Daily!G2787 -> 42952.609 | E30: 2024-01-31T21:00:00+00:00 | F30: 2024-01-31T00:00:00+00:00
A31: 2024-02-29 | B31: 2024-02-29T21:00:00+00:00 | C31: =Daily!G886 -> 189.31 | D31: =Daily!G2816 -> 62504.789 | E31: 2024-02-29T21:00:00+00:00 | F31: 2024-02-29T00:00:00+00:00
A32: 2024-03-28 | B32: 2024-03-28T20:00:00+00:00 | C32: =Daily!G906 -> 205.72 | D32: =Daily!G2844 -> 69455.344 | E32: 2024-03-28T20:00:00+00:00 | F32: 2024-03-28T00:00:00+00:00
A33: 2024-04-30 | B33: 2024-04-30T20:00:00+00:00 | C33: =Daily!G928 -> 211.87 | D33: =Daily!G2877 -> 63841.121 | E33: 2024-04-30T20:00:00+00:00 | F33: 2024-04-30T00:00:00+00:00
A34: 2024-05-31 | B34: 2024-05-31T20:00:00+00:00 | C34: =Daily!G950 -> 215.3 | D34: =Daily!G2908 -> 68364.992 | E34: 2024-05-31T20:00:00+00:00 | F34: 2024-05-31T00:00:00+00:00
A35: 2024-06-28 | B35: 2024-06-28T20:00:00+00:00 | C35: =Daily!G969 -> 215.00999 | D35: =Daily!G2936 -> 61604.801 | E35: 2024-06-28T20:00:00+00:00 | F35: 2024-06-28T00:00:00+00:00
A36: 2024-07-31 | B36: 2024-07-31T20:00:00+00:00 | C36: =Daily!G991 -> 226.55 | D36: =Daily!G2969 -> 66201.016 | E36: 2024-07-31T20:00:00+00:00 | F36: 2024-07-31T00:00:00+00:00
A37: 2024-08-30 | B37: 2024-08-30T20:00:00+00:00 | C37: =Daily!G1013 -> 231.28999 | D37: =Daily!G2999 -> 59388.18 | E37: 2024-08-30T20:00:00+00:00 | F37: 2024-08-30T00:00:00+00:00
A38: 2024-09-30 | B38: 2024-09-30T20:00:00+00:00 | C38: =Daily!G1033 -> 243.06 | D38: =Daily!G3030 -> 65635.305 | E38: 2024-09-30T20:00:00+00:00 | F38: 2024-09-30T00:00:00+00:00
A39: 2024-10-31 | B39: 2024-10-31T20:00:00+00:00 | C39: =Daily!G1056 -> 253.50999 | D39: =Daily!G3061 -> 72339.539 | E39: 2024-10-31T20:00:00+00:00 | F39: 2024-10-31T00:00:00+00:00
A40: 2024-11-29 | B40: 2024-11-29T18:00:00+00:00 | C40: =Daily!G1076 -> 245.59 | D40: =Daily!G3090 -> 95652.469 | E40: 2024-11-29T18:00:00+00:00 | F40: 2024-11-29T00:00:00+00:00
...

Sheet MonthlyCalc
A1: 估值日期 | B1: GLD 调仓前 | C1: BTC-USD 调仓前 | D1: 费用前资产 | E1: 再平衡 | F1: 成交额近似 | G1: 费用 | H1: 净资产 | I1: GLD 调仓后 | J1: BTC-USD 调仓后 | K1: 历史峰值 | L1: 回撤 | M1: 期间收益 | N1: Python 初始校验 | O1: 初始参数差额
A2: =Monthly!A2 -> 2021-09-30 | B2: =Parameters!$B$2*Parameters!$B$8 -> 60000 | C2: =Parameters!$B$2*Parameters!$B$9 -> 40000 | D2: =SUM(B2:C2) -> 100000 | E2: =TRUE() -> TRUE | F2: =D2 -> 100000 | G2: =IF(E2,F2*Parameters!$B$3/10000,0) -> 200 | H2: =IF(ABS(Parameters!$B$5-1)>0.00000001,NA(),D2-G2) -> 99800 | I2: =IF(E2,H2*Parameters!$B$8,B2) -> 59880 | J2: =IF(E2,H2*Parameters!$B$9,C2) -> 39920 | K2: =MAX(Parameters!$B$2,H$2:H2) -> 100000 | L2: =H2/K2-1 -> -0.002 | M2: =H2/Parameters!$B$2-1 -> -0.002 | N2: 99800 | O2: =H2-N2 -> 0
A3: =Monthly!A3 -> 2021-10-29 | B3: =I2*Monthly!C3/Monthly!C2 -> 60766.055 | C3: =J2*Monthly!D3/Monthly!D2 -> 58223.813 | D3: =SUM(B3:C3) -> 118989.87 | E3: =IF(Parameters!$B$4=0,FALSE(),MOD(1,Parameters!$B$4)=0) -> FALSE | F3: =ABS(D3*Parameters!$B$8-B3)+ABS(D3*Parameters!$B$9-C3) -> 0 | G3: =IF(E3,F3*Parameters!$B$3/10000,0) -> 0 | H3: =IF(ABS(Parameters!$B$5-1)>0.00000001,NA(),D3-G3) -> 118989.87 | I3: =IF(E3,H3*Parameters!$B$8,B3) -> 60766.055 | J3: =IF(E3,H3*Parameters!$B$9,C3) -> 58223.813 | K3: =MAX(Parameters!$B$2,H$2:H3) -> 118989.87 | L3: =H3/K3-1 -> 0 | M3: =H3/H2-1 -> 0.19228324 | N3: 118989.87 | O3: =H3-N3 -> 0
A4: =Monthly!A4 -> 2021-11-30 | B4: =I3*Monthly!C4/Monthly!C3 -> 60346.73 | C4: =J3*Monthly!D4/Monthly!D3 -> 55519.631 | D4: =SUM(B4:C4) -> 115866.36 | E4: =IF(Parameters!$B$4=0,FALSE(),MOD(2,Parameters!$B$4)=0) -> FALSE | F4: =ABS(D4*Parameters!$B$8-B4)+ABS(D4*Parameters!$B$9-C4) -> 0 | G4: =IF(E4,F4*Parameters!$B$3/10000,0) -> 0 | H4: =IF(ABS(Parameters!$B$5-1)>0.00000001,NA(),D4-G4) -> 115866.36 | I4: =IF(E4,H4*Parameters!$B$8,B4) -> 60346.73 | J4: =IF(E4,H4*Parameters!$B$9,C4) -> 55519.631 | K4: =MAX(Parameters!$B$2,H$2:H4) -> 118989.87 | L4: =H4/K4-1 -> -0.02625019 | M4: =H4/H3-1 -> -0.02625019 | N4: 115866.36 | O4: =H4-N4 -> 0
A5: =Monthly!A5 -> 2021-12-31 | B5: =I4*Monthly!C5/Monthly!C4 -> 62337.627 | C5: =J4*Monthly!D5/Monthly!D4 -> 45311.671 | D5: =SUM(B5:C5) -> 107649.3 | E5: =IF(Parameters!$B$4=0,FALSE(),MOD(3,Parameters!$B$4)=0) -> TRUE | F5: =ABS(D5*Parameters!$B$8-B5)+ABS(D5*Parameters!$B$9-C5) -> 4503.9034 | G5: =IF(E5,F5*Parameters!$B$3/10000,0) -> 9.0078068 | H5: =IF(ABS(Parameters!$B$5-1)>0.00000001,NA(),D5-G5) -> 107640.29 | I5: =IF(E5,H5*Parameters!$B$8,B5) -> 64584.174 | J5: =IF(E5,H5*Parameters!$B$9,C5) -> 43056.116 | K5: =MAX(Parameters!$B$2,H$2:H5) -> 118989.87 | L5: =H5/K5-1 -> -0.095382722 | M5: =H5/H4-1 -> -0.070996195 | N5: 107640.29 | O5: =H5-N5 -> 0
A6: =Monthly!A6 -> 2022-01-31 | B6: =I5*Monthly!C6/Monthly!C5 -> 63499.96 | C6: =J5*Monthly!D6/Monthly!D5 -> 34604.696 | D6: =SUM(B6:C6) -> 98104.656 | E6: =IF(Parameters!$B$4=0,FALSE(),MOD(4,Parameters!$B$4)=0) -> FALSE | F6: =ABS(D6*Parameters!$B$8-B6)+ABS(D6*Parameters!$B$9-C6) -> 0 | G6: =IF(E6,F6*Parameters!$B$3/10000,0) -> 0 | H6: =IF(ABS(Parameters!$B$5-1)>0.00000001,NA(),D6-G6) -> 98104.656 | I6: =IF(E6,H6*Parameters!$B$8,B6) -> 63499.96 | J6: =IF(E6,H6*Parameters!$B$9,C6) -> 34604.696 | K6: =MAX(Parameters!$B$2,H$2:H6) -> 118989.87 | L6: =H6/K6-1 -> -0.17552093 | M6: =H6/H5-1 -> -0.088587968 | N6: 98104.656 | O6: =H6-N6 -> 0
A7: =Monthly!A7 -> 2022-02-28 | B7: =I6*Monthly!C7/Monthly!C6 -> 67387.253 | C7: =J6*Monthly!D7/Monthly!D6 -> 34415.036 | D7: =SUM(B7:C7) -> 101802.29 | E7: =IF(Parameters!$B$4=0,FALSE(),MOD(5,Parameters!$B$4)=0) -> FALSE | F7: =ABS(D7*Parameters!$B$8-B7)+ABS(D7*Parameters!$B$9-C7) -> 0 | G7: =IF(E7,F7*Parameters!$B$3/10000,0) -> 0 | H7: =IF(ABS(Parameters!$B$5-1)>0.00000001,NA(),D7-G7) -> 101802.29 | I7: =IF(E7,H7*Parameters!$B$8,B7) -> 67387.253 | J7: =IF(E7,H7*Parameters!$B$9,C7) -> 34415.036 | K7: =MAX(Parameters!$B$2,H$2:H7) -> 118989.87 | L7: =H7/K7-1 -> -0.14444573 | M7: =H7/H6-1 -> 0.03769071 | N7: 101802.29 | O7: =H7-N7 -> 0
A8: =Monthly!A8 -> 2022-03-31 | B8: =I7*Monthly!C8/Monthly!C7 -> 68244.795 | C8: =J7*Monthly!D8/Monthly!D7 -> 42950.743 | D8: =SUM(B8:C8) -> 111195.54 | E8: =IF(Parameters!$B$4=0,FALSE(),MOD(6,Parameters!$B$4)=0) -> TRUE | F8: =ABS(D8*Parameters!$B$8-B8)+ABS(D8*Parameters!$B$9-C8) -> 3054.9445 | G8: =IF(E8,F8*Parameters!$B$3/10000,0) -> 6.109889 | H8: =IF(ABS(Parameters!$B$5-1)>0.00000001,NA(),D8-G8) -> 111189.43 | I8: =IF(E8,H8*Parameters!$B$8,B8) -> 66713.657 | J8: =IF(E8,H8*Parameters!$B$9,C8) -> 44475.771 | K8: =MAX(Parameters!$B$2,H$2:H8) -> 118989.87 | L8: =H8/K8-1 -> -0.06555549 | M8: =H8/H7-1 -> 0.092209505 | N8: 111189.43 | O8: =H8-N8 -> 0
A9: =Monthly!A9 -> 2022-04-29 | B9: =I8*Monthly!C9/Monthly!C8 -> 65332.487 | C9: =J8*Monthly!D9/Monthly!D8 -> 37587.581 | D9: =SUM(B9:C9) -> 102920.07 | E9: =IF(Parameters!$B$4=0,FALSE(),MOD(7,Parameters!$B$4)=0) -> FALSE | F9: =ABS(D9*Parameters!$B$8-B9)+ABS(D9*Parameters!$B$9-C9) -> 0 | G9: =IF(E9,F9*Parameters!$B$3/10000,0) -> 0 | H9: =IF(ABS(Parameters!$B$5-1)>0.00000001,NA(),D9-G9) -> 102920.07 | I9: =IF(E9,H9*Parameters!$B$8,B9) -> 65332.487 | J9: =IF(E9,H9*Parameters!$B$9,C9) -> 37587.581 | K9: =MAX(Parameters!$B$2,H$2:H9) -> 118989.87 | L9: =H9/K9-1 -> -0.13505184 | M9: =H9/H8-1 -> -0.074371828 | N9: 102920.07 | O9: =H9-N9 -> 0
A10: =Monthly!A10 -> 2022-05-31 | B10: =I9*Monthly!C10/Monthly!C9 -> 63201.636 | C10: =J9*Monthly!D10/Monthly!D9 -> 29982.487 | D10: =SUM(B10:C10) -> 93184.123 | E10: =IF(Parameters!$B$4=0,FALSE(),MOD(8,Parameters!$B$4)=0) -> FALSE | F10: =ABS(D10*Parameters!$B$8-B10)+ABS(D10*Parameters!$B$9-C10) -> 0 | G10: =IF(E10,F10*Parameters!$B$3/10000,0) -> 0 | H10: =IF(ABS(Parameters!$B$5-1)>0.00000001,NA(),D10-G10) -> 93184.123 | I10: =IF(E10,H10*Parameters!$B$8,B10) -> 63201.636 | J10: =IF(E10,H10*Parameters!$B$9,C10) -> 29982.487 | K10: =MAX(Parameters!$B$2,H$2:H10) -> 118989.87 | L10: =H10/K10-1 -> -0.21687346 | M10: =H10/H9-1 -> -0.094597144 | N10: 93184.123 | O10: =H10-N10 -> 0
A11: =Monthly!A11 -> 2022-06-30 | B11: =I10*Monthly!C11/Monthly!C10 -> 62211.921 | C11: =J10*Monthly!D11/Monthly!D10 -> 18998.966 | D11: =SUM(B11:C11) -> 81210.887 | E11: =IF(Parameters!$B$4=0,FALSE(),MOD(9,Parameters!$B$4)=0) -> TRUE | F11: =ABS(D11*Parameters!$B$8-B11)+ABS(D11*Parameters!$B$9-C11) -> 26970.778 | G11: =IF(E11,F11*Parameters!$B$3/10000,0) -> 53.941555 | H11: =IF(ABS(Parameters!$B$5-1)>0.00000001,NA(),D11-G11) -> 81156.945 | I11: =IF(E11,H11*Parameters!$B$8,B11) -> 48694.167 | J11: =IF(E11,H11*Parameters!$B$9,C11) -> 32462.778 | K11: =MAX(Parameters!$B$2,H$2:H11) -> 118989.87 | L11: =H11/K11-1 -> -0.31795079 | M11: =H11/H10-1 -> -0.12906896 | N11: 81156.945 | O11: =H11-N11 -> 0
A12: =Monthly!A12 -> 2022-07-29 | B12: =I11*Monthly!C12/Monthly!C11 -> 47433.888 | C12: =J11*Monthly!D12/Monthly!D11 -> 38501.686 | D12: =SUM(B12:C12) -> 85935.574 | E12: =IF(Parameters!$B$4=0,FALSE(),MOD(10,Parameters!$B$4)=0) -> FALSE | F12: =ABS(D12*Parameters!$B$8-B12)+ABS(D12*Parameters!$B$9-C12) -> 0 | G12: =IF(E12,F12*Parameters!$B$3/10000,0) -> 0 | H12: =IF(ABS(Parameters!$B$5-1)>0.00000001,NA(),D12-G12) -> 85935.574 | I12: =IF(E12,H12*Parameters!$B$8,B12) -> 47433.888 | J12: =IF(E12,H12*Parameters!$B$9,C12) -> 38501.686 | K12: =MAX(Parameters!$B$2,H$2:H12) -> 118989.87 | L12: =H12/K12-1 -> -0.27779082 | M12: =H12/H11-1 -> 0.058881335 | N12: 85935.574 | O12: =H12-N12 -> 0
A13: =Monthly!A13 -> 2022-08-31 | B13: =I12*Monthly!C13/Monthly!C12 -> 46037.753 | C13: =J12*Monthly!D13/Monthly!D12 -> 31966.706 | D13: =SUM(B13:C13) -> 78004.459 | E13: =IF(Parameters!$B$4=0,FALSE(),MOD(11,Parameters!$B$4)=0) -> FALSE | F13: =ABS(D13*Parameters!$B$8-B13)+ABS(D13*Parameters!$B$9-C13) -> 0 | G13: =IF(E13,F13*Parameters!$B$3/10000,0) -> 0 | H13: =IF(ABS(Parameters!$B$5-1)>0.00000001,NA(),D13-G13) -> 78004.459 | I13: =IF(E13,H13*Parameters!$B$8,B13) -> 46037.753 | J13: =IF(E13,H13*Parameters!$B$9,C13) -> 31966.706 | K13: =MAX(Parameters!$B$2,H$2:H13) -> 118989.87 | L13: =H13/K13-1 -> -0.34444453 | M13: =H13/H12-1 -> -0.092291411 | N13: 78004.459 | O13: =H13-N13 -> 0
A14: =Monthly!A14 -> 2022-09-30 | B14: =I13*Monthly!C14/Monthly!C13 -> 44708.1 | C14: =J13*Monthly!D14/Monthly!D13 -> 31605.395 | D14: =SUM(B14:C14) -> 76313.495 | E14: =IF(Parameters!$B$4=0,FALSE(),MOD(12,Parameters!$B$4)=0) -> TRUE | F14: =ABS(D14*Parameters!$B$8-B14)+ABS(D14*Parameters!$B$9-C14) -> 2159.9945 | G14: =IF(E14,F14*Parameters!$B$3/10000,0) -> 4.3199891 | H14: =IF(ABS(Parameters!$B$5-1)>0.00000001,NA(),D14-G14) -> 76309.175 | I14: =IF(E14,H14*Parameters!$B$8,B14) -> 45785.505 | J14: =IF(E14,H14*Parameters!$B$9,C14) -> 30523.67 | K14: =MAX(Parameters!$B$2,H$2:H14) -> 118989.87 | L14: =H14/K14-1 -> -0.35869183 | M14: =H14/H13-1 -> -0.021733173 | N14: 76309.175 | O14: =H14-N14 -> 0
A15: =Monthly!A15 -> 2022-10-31 | B15: =I14*Monthly!C15/Monthly!C14 -> 44968.49 | C15: =J14*Monthly!D15/Monthly!D14 -> 32180.694 | D15: =SUM(B15:C15) -> 77149.183 | E15: =IF(Parameters!$B$4=0,FALSE(),MOD(13,Parameters!$B$4)=0) -> FALSE | F15: =ABS(D15*Parameters!$B$8-B15)+ABS(D15*Parameters!$B$9-C15) -> 0 | G15: =IF(E15,F15*Parameters!$B$3/10000,0) -> 0 | H15: =IF(ABS(Parameters!$B$5-1)>0.00000001,NA(),D15-G15) -> 77149.183 | I15: =IF(E15,H15*Parameters!$B$8,B15) -> 44968.49 | J15: =IF(E15,H15*Parameters!$B$9,C15) -> 32180.694 | K15: =MAX(Parameters!$B$2,H$2:H15) -> 118989.87 | L15: =H15/K15-1 -> -0.35163233 | M15: =H15/H14-1 -> 0.011007962 | N15: 77149.183 | O15: =H15-N15 -> 0
A16: =Monthly!A16 -> 2022-11-30 | B16: =I15*Monthly!C16/Monthly!C15 -> 48787.153 | C16: =J15*Monthly!D16/Monthly!D15 -> 25645.528 | D16: =SUM(B16:C16) -> 74432.681 | E16: =IF(Parameters!$B$4=0,FALSE(),MOD(14,Parameters!$B$4)=0) -> FALSE | F16: =ABS(D16*Parameters!$B$8-B16)+ABS(D16*Parameters!$B$9-C16) -> 0 | G16: =IF(E16,F16*Parameters!$B$3/10000,0) -> 0 | H16: =IF(ABS(Parameters!$B$5-1)>0.00000001,NA(),D16-G16) -> 74432.681 | I16: =IF(E16,H16*Parameters!$B$8,B16) -> 48787.153 | J16: =IF(E16,H16*Parameters!$B$9,C16) -> 25645.528 | K16: =MAX(Parameters!$B$2,H$2:H16) -> 118989.87 | L16: =H16/K16-1 -> -0.37446202 | M16: =H16/H15-1 -> -0.035211028 | N16: 74432.681 | O16: =H16-N16 -> 0
A17: =Monthly!A17 -> 2022-12-30 | B17: =I16*Monthly!C17/Monthly!C16 -> 50216.933 | C17: =J16*Monthly!D17/Monthly!D16 -> 25953.304 | D17: =SUM(B17:C17) -> 76170.238 | E17: =IF(Parameters!$B$4=0,FALSE(),MOD(15,Parameters!$B$4)=0) -> TRUE | F17: =ABS(D17*Parameters!$B$8-B17)+ABS(D17*Parameters!$B$9-C17) -> 9029.5814 | G17: =IF(E17,F17*Parameters!$B$3/10000,0) -> 18.059163 | H17: =IF(ABS(Parameters!$B$5-1)>0.00000001,NA(),D17-G17) -> 76152.179 | I17: =IF(E17,H17*Parameters!$B$8,B17) -> 45691.307 | J17: =IF(E17,H17*Parameters!$B$9,C17) -> 30460.871 | K17: =MAX(Parameters!$B$2,H$2:H17) -> 118989.87 | L17: =H17/K17-1 -> -0.36001123 | M17: =H17/H16-1 -> 0.023101381 | N17: 76152.179 | O17: =H17-N17 -> 0
A18: =Monthly!A18 -> 2023-01-31 | B18: =I17*Monthly!C18/Monthly!C17 -> 48322.787 | C18: =J17*Monthly!D18/Monthly!D17 -> 41804.846 | D18: =SUM(B18:C18) -> 90127.633 | E18: =IF(Parameters!$B$4=0,FALSE(),MOD(16,Parameters!$B$4)=0) -> FALSE | F18: =ABS(D18*Parameters!$B$8-B18)+ABS(D18*Parameters!$B$9-C18) -> 0 | G18: =IF(E18,F18*Parameters!$B$3/10000,0) -> 0 | H18: =IF(ABS(Parameters!$B$5-1)>0.00000001,NA(),D18-G18) -> 90127.633 | I18: =IF(E18,H18*Parameters!$B$8,B18) -> 48322.787 | J18: =IF(E18,H18*Parameters!$B$9,C18) -> 41804.846 | K18: =MAX(Parameters!$B$2,H$2:H18) -> 118989.87 | L18: =H18/K18-1 -> -0.24256044 | M18: =H18/H17-1 -> 0.18352008 | N18: 90127.633 | O18: =H18-N18 -> 0
A19: =Monthly!A19 -> 2023-02-28 | B19: =I18*Monthly!C19/Monthly!C18 -> 45729.015 | C19: =J18*Monthly!D19/Monthly!D18 -> 43054.467 | D19: =SUM(B19:C19) -> 88783.482 | E19: =IF(Parameters!$B$4=0,FALSE(),MOD(17,Parameters!$B$4)=0) -> FALSE | F19: =ABS(D19*Parameters!$B$8-B19)+ABS(D19*Parameters!$B$9-C19) -> 0 | G19: =IF(E19,F19*Parameters!$B$3/10000,0) -> 0 | H19: =IF(ABS(Parameters!$B$5-1)>0.00000001,NA(),D19-G19) -> 88783.482 | I19: =IF(E19,H19*Parameters!$B$8,B19) -> 45729.015 | J19: =IF(E19,H19*Parameters!$B$9,C19) -> 43054.467 | K19: =MAX(Parameters!$B$2,H$2:H19) -> 118989.87 | L19: =H19/K19-1 -> -0.25385679 | M19: =H19/H18-1 -> -0.01491386 | N19: 88783.482 | O19: =H19-N19 -> 0
A20: =Monthly!A20 -> 2023-03-31 | B20: =I19*Monthly!C20/Monthly!C19 -> 49348.983 | C20: =J19*Monthly!D20/Monthly!D19 -> 51310.492 | D20: =SUM(B20:C20) -> 100659.47 | E20: =IF(Parameters!$B$4=0,FALSE(),MOD(18,Parameters!$B$4)=0) -> TRUE | F20: =ABS(D20*Parameters!$B$8-B20)+ABS(D20*Parameters!$B$9-C20) -> 22093.404 | G20: =IF(E20,F20*Parameters!$B$3/10000,0) -> 44.186809 | H20: =IF(ABS(Parameters!$B$5-1)>0.00000001,NA(),D20-G20) -> 100615.29 | I20: =IF(E20,H20*Parameters!$B$8,B20) -> 60369.173 | J20: =IF(E20,H20*Parameters!$B$9,C20) -> 40246.115 | K20: =MAX(Parameters!$B$2,H$2:H20) -> 118989.87 | L20: =H20/K20-1 -> -0.15442138 | M20: =H20/H19-1 -> 0.13326585 | N20: 100615.29 | O20: =H20-N20 -> 0
A21: =Monthly!A21 -> 2023-04-28 | B21: =I20*Monthly!C21/Monthly!C20 -> 60889.768 | C21: =J20*Monthly!D21/Monthly!D20 -> 42313.76 | D21: =SUM(B21:C21) -> 103203.53 | E21: =IF(Parameters!$B$4=0,FALSE(),MOD(19,Parameters!$B$4)=0) -> FALSE | F21: =ABS(D21*Parameters!$B$8-B21)+ABS(D21*Parameters!$B$9-C21) -> 0 | G21: =IF(E21,F21*Parameters!$B$3/10000,0) -> 0 | H21: =IF(ABS(Parameters!$B$5-1)>0.00000001,NA(),D21-G21) -> 103203.53 | I21: =IF(E21,H21*Parameters!$B$8,B21) -> 60889.768 | J21: =IF(E21,H21*Parameters!$B$9,C21) -> 42313.76 | K21: =MAX(Parameters!$B$2,H$2:H21) -> 118989.87 | L21: =H21/K21-1 -> -0.13266962 | M21: =H21/H20-1 -> 0.025724118 | N21: 103203.53 | O21: =H21-N21 -> 0
A22: =Monthly!A22 -> 2023-05-31 | B22: =I21*Monthly!C22/Monthly!C21 -> 60072.634 | C22: =J21*Monthly!D22/Monthly!D21 -> 39770.612 | D22: =SUM(B22:C22) -> 99843.246 | E22: =IF(Parameters!$B$4=0,FALSE(),MOD(20,Parameters!$B$4)=0) -> FALSE | F22: =ABS(D22*Parameters!$B$8-B22)+ABS(D22*Parameters!$B$9-C22) -> 0 | G22: =IF(E22,F22*Parameters!$B$3/10000,0) -> 0 | H22: =IF(ABS(Parameters!$B$5-1)>0.00000001,NA(),D22-G22) -> 99843.246 | I22: =IF(E22,H22*Parameters!$B$8,B22) -> 60072.634 | J22: =IF(E22,H22*Parameters!$B$9,C22) -> 39770.612 | K22: =MAX(Parameters!$B$2,H$2:H22) -> 118989.87 | L22: =H22/K22-1 -> -0.16090968 | M22: =H22/H21-1 -> -0.032559752 | N22: 99843.246 | O22: =H22-N22 -> 0
A23: =Monthly!A23 -> 2023-06-30 | B23: =I22*Monthly!C23/Monthly!C22 -> 58738.198 | C23: =J22*Monthly!D23/Monthly!D22 -> 43708.577 | D23: =SUM(B23:C23) -> 102446.77 | E23: =IF(Parameters!$B$4=0,FALSE(),MOD(21,Parameters!$B$4)=0) -> TRUE | F23: =ABS(D23*Parameters!$B$8-B23)+ABS(D23*Parameters!$B$9-C23) -> 5459.7341 | G23: =IF(E23,F23*Parameters!$B$3/10000,0) -> 10.919468 | H23: =IF(ABS(Parameters!$B$5-1)>0.00000001,NA(),D23-G23) -> 102435.86 | I23: =IF(E23,H23*Parameters!$B$8,B23) -> 61461.513 | J23: =IF(E23,H23*Parameters!$B$9,C23) -> 40974.342 | K23: =MAX(Parameters!$B$2,H$2:H23) -> 118989.87 | L23: =H23/K23-1 -> -0.13912119 | M23: =H23/H22-1 -> 0.025966795 | N23: 102435.86 | O23: =H23-N23 -> 0
A24: =Monthly!A24 -> 2023-07-31 | B24: =I23*Monthly!C24/Monthly!C23 -> 62868.161 | C24: =J23*Monthly!D24/Monthly!D23 -> 39399.66 | D24: =SUM(B24:C24) -> 102267.82 | E24: =IF(Parameters!$B$4=0,FALSE(),MOD(22,Parameters!$B$4)=0) -> FALSE | F24: =ABS(D24*Parameters!$B$8-B24)+ABS(D24*Parameters!$B$9-C24) -> 0 | G24: =IF(E24,F24*Parameters!$B$3/10000,0) -> 0 | H24: =IF(ABS(Parameters!$B$5-1)>0.00000001,NA(),D24-G24) -> 102267.82 | I24: =IF(E24,H24*Parameters!$B$8,B24) -> 62868.161 | J24: =IF(E24,H24*Parameters!$B$9,C24) -> 39399.66 | K24: =MAX(Parameters!$B$2,H$2:H24) -> 118989.87 | L24: =H24/K24-1 -> -0.14053337 | M24: =H24/H23-1 -> -0.0016403839 | N24: 102267.82 | O24: =H24-N24 -> 0
A25: =Monthly!A25 -> 2023-08-31 | B25: =I24*Monthly!C25/Monthly!C24 -> 62064.854 | C25: =J24*Monthly!D25/Monthly!D24 -> 36737.546 | D25: =SUM(B25:C25) -> 98802.4 | E25: =IF(Parameters!$B$4=0,FALSE(),MOD(23,Parameters!$B$4)=0) -> FALSE | F25: =ABS(D25*Parameters!$B$8-B25)+ABS(D25*Parameters!$B$9-C25) -> 0 | G25: =IF(E25,F25*Parameters!$B$3/10000,0) -> 0 | H25: =IF(ABS(Parameters!$B$5-1)>0.00000001,NA(),D25-G25) -> 98802.4 | I25: =IF(E25,H25*Parameters!$B$8,B25) -> 62064.854 | J25: =IF(E25,H25*Parameters!$B$9,C25) -> 36737.546 | K25: =MAX(Parameters!$B$2,H$2:H25) -> 118989.87 | L25: =H25/K25-1 -> -0.16965703 | M25: =H25/H24-1 -> -0.03388574 | N25: 98802.4 | O25: =H25-N25 -> 0
A26: =Monthly!A26 -> 2023-09-29 | B26: =I25*Monthly!C26/Monthly!C25 -> 59110.204 | C26: =J25*Monthly!D26/Monthly!D25 -> 36366.475 | D26: =SUM(B26:C26) -> 95476.678 | E26: =IF(Parameters!$B$4=0,FALSE(),MOD(24,Parameters!$B$4)=0) -> TRUE | F26: =ABS(D26*Parameters!$B$8-B26)+ABS(D26*Parameters!$B$9-C26) -> 3648.3933 | G26: =IF(E26,F26*Parameters!$B$3/10000,0) -> 7.2967865 | H26: =IF(ABS(Parameters!$B$5-1)>0.00000001,NA(),D26-G26) -> 95469.381 | I26: =IF(E26,H26*Parameters!$B$8,B26) -> 57281.629 | J26: =IF(E26,H26*Parameters!$B$9,C26) -> 38187.753 | K26: =MAX(Parameters!$B$2,H$2:H26) -> 118989.87 | L26: =H26/K26-1 -> -0.19766798 | M26: =H26/H25-1 -> -0.033734189 | N26: 95469.381 | O26: =H26-N26 -> 0
A27: =Monthly!A27 -> 2023-10-31 | B27: =I26*Monthly!C27/Monthly!C26 -> 61504.666 | C27: =J26*Monthly!D27/Monthly!D26 -> 48759.892 | D27: =SUM(B27:C27) -> 110264.56 | E27: =IF(Parameters!$B$4=0,FALSE(),MOD(25,Parameters!$B$4)=0) -> FALSE | F27: =ABS(D27*Parameters!$B$8-B27)+ABS(D27*Parameters!$B$9-C27) -> 0 | G27: =IF(E27,F27*Parameters!$B$3/10000,0) -> 0 | H27: =IF(ABS(Parameters!$B$5-1)>0.00000001,NA(),D27-G27) -> 110264.56 | I27: =IF(E27,H27*Parameters!$B$8,B27) -> 61504.666 | J27: =IF(E27,H27*Parameters!$B$9,C27) -> 48759.892 | K27: =MAX(Parameters!$B$2,H$2:H27) -> 118989.87 | L27: =H27/K27-1 -> -0.07332817 | M27: =H27/H26-1 -> 0.15497301 | N27: 110264.56 | O27: =H27-N27 -> 0
A28: =Monthly!A28 -> 2023-11-30 | B28: =I27*Monthly!C28/Monthly!C27 -> 63061.578 | C28: =J27*Monthly!D28/Monthly!D27 -> 53502.886 | D28: =SUM(B28:C28) -> 116564.46 | E28: =IF(Parameters!$B$4=0,FALSE(),MOD(26,Parameters!$B$4)=0) -> FALSE | F28: =ABS(D28*Parameters!$B$8-B28)+ABS(D28*Parameters!$B$9-C28) -> 0 | G28: =IF(E28,F28*Parameters!$B$3/10000,0) -> 0 | H28: =IF(ABS(Parameters!$B$5-1)>0.00000001,NA(),D28-G28) -> 116564.46 | I28: =IF(E28,H28*Parameters!$B$8,B28) -> 63061.578 | J28: =IF(E28,H28*Parameters!$B$9,C28) -> 53502.886 | K28: =MAX(Parameters!$B$2,H$2:H28) -> 118989.87 | L28: =H28/K28-1 -> -0.020383278 | M28: =H28/H27-1 -> 0.057134457 | N28: 116564.46 | O28: =H28-N28 -> 0
A29: =Monthly!A29 -> 2023-12-29 | B29: =I28*Monthly!C29/Monthly!C28 -> 63870.102 | C29: =J28*Monthly!D29/Monthly!D28 -> 60243.109 | D29: =SUM(B29:C29) -> 124113.21 | E29: =IF(Parameters!$B$4=0,FALSE(),MOD(27,Parameters!$B$4)=0) -> TRUE | F29: =ABS(D29*Parameters!$B$8-B29)+ABS(D29*Parameters!$B$9-C29) -> 21195.649 | G29: =IF(E29,F29*Parameters!$B$3/10000,0) -> 42.391298 | H29: =IF(ABS(Parameters!$B$5-1)>0.00000001,NA(),D29-G29) -> 124070.82 | I29: =IF(E29,H29*Parameters!$B$8,B29) -> 74442.492 | J29: =IF(E29,H29*Parameters!$B$9,C29) -> 49628.328 | K29: =MAX(Parameters!$B$2,H$2:H29) -> 124070.82 | L29: =H29/K29-1 -> 0 | M29: =H29/H28-1 -> 0.064396609 | N29: 124070.82 | O29: =H29-N29 -> 0
A30: =Monthly!A30 -> 2024-01-31 | B30: =I29*Monthly!C30/Monthly!C29 -> 73383.311 | C30: =J29*Monthly!D30/Monthly!D29 -> 50006.414 | D30: =SUM(B30:C30) -> 123389.73 | E30: =IF(Parameters!$B$4=0,FALSE(),MOD(28,Parameters!$B$4)=0) -> FALSE | F30: =ABS(D30*Parameters!$B$8-B30)+ABS(D30*Parameters!$B$9-C30) -> 0 | G30: =IF(E30,F30*Parameters!$B$3/10000,0) -> 0 | H30: =IF(ABS(Parameters!$B$5-1)>0.00000001,NA(),D30-G30) -> 123389.73 | I30: =IF(E30,H30*Parameters!$B$8,B30) -> 73383.311 | J30: =IF(E30,H30*Parameters!$B$9,C30) -> 50006.414 | K30: =MAX(Parameters!$B$2,H$2:H30) -> 124070.82 | L30: =H30/K30-1 -> -0.0054895684 | M30: =H30/H29-1 -> -0.0054895684 | N30: 123389.73 | O30: =H30-N30 -> 0
A31: =Monthly!A31 -> 2024-02-29 | B31: =I30*Monthly!C31/Monthly!C30 -> 73718.199 | C31: =J30*Monthly!D31/Monthly!D30 -> 72769.511 | D31: =SUM(B31:C31) -> 146487.71 | E31: =IF(Parameters!$B$4=0,FALSE(),MOD(29,Parameters!$B$4)=0) -> FALSE | F31: =ABS(D31*Parameters!$B$8-B31)+ABS(D31*Parameters!$B$9-C31) -> 0 | G31: =IF(E31,F31*Parameters!$B$3/10000,0) -> 0 | H31: =IF(ABS(Parameters!$B$5-1)>0.00000001,NA(),D31-G31) -> 146487.71 | I31: =IF(E31,H31*Parameters!$B$8,B31) -> 73718.199 | J31: =IF(E31,H31*Parameters!$B$9,C31) -> 72769.511 | K31: =MAX(Parameters!$B$2,H$2:H31) -> 146487.71 | L31: =H31/K31-1 -> 0 | M31: =H31/H30-1 -> 0.18719537 | N31: 146487.71 | O31: =H31-N31 -> 0
A32: =Monthly!A32 -> 2024-03-28 | B32: =I31*Monthly!C32/Monthly!C31 -> 80108.331 | C32: =J31*Monthly!D32/Monthly!D31 -> 80861.506 | D32: =SUM(B32:C32) -> 160969.84 | E32: =IF(Parameters!$B$4=0,FALSE(),MOD(30,Parameters!$B$4)=0) -> TRUE | F32: =ABS(D32*Parameters!$B$8-B32)+ABS(D32*Parameters!$B$9-C32) -> 32947.142 | G32: =IF(E32,F32*Parameters!$B$3/10000,0) -> 65.894284 | H32: =IF(ABS(Parameters!$B$5-1)>0.00000001,NA(),D32-G32) -> 160903.94 | I32: =IF(E32,H32*Parameters!$B$8,B32) -> 96542.366 | J32: =IF(E32,H32*Parameters!$B$9,C32) -> 64361.577 | K32: =MAX(Parameters!$B$2,H$2:H32) -> 160903.94 | L32: =H32/K32-1 -> 0 | M32: =H32/H31-1 -> 0.098412579 | N32: 160903.94 | O32: =H32-N32 -> 0
A33: =Monthly!A33 -> 2024-04-30 | B33: =I32*Monthly!C33/Monthly!C32 -> 99428.497 | C33: =J32*Monthly!D33/Monthly!D32 -> 59159.095 | D33: =SUM(B33:C33) -> 158587.59 | E33: =IF(Parameters!$B$4=0,FALSE(),MOD(31,Parameters!$B$4)=0) -> FALSE | F33: =ABS(D33*Parameters!$B$8-B33)+ABS(D33*Parameters!$B$9-C33) -> 0 | G33: =IF(E33,F33*Parameters!$B$3/10000,0) -> 0 | H33: =IF(ABS(Parameters!$B$5-1)>0.00000001,NA(),D33-G33) -> 158587.59 | I33: =IF(E33,H33*Parameters!$B$8,B33) -> 99428.497 | J33: =IF(E33,H33*Parameters!$B$9,C33) -> 59159.095 | K33: =MAX(Parameters!$B$2,H$2:H33) -> 160903.94 | L33: =H33/K33-1 -> -0.014395864 | M33: =H33/H32-1 -> -0.014395864 | N33: 158587.59 | O33: =H33-N33 -> 0
A34: =Monthly!A34 -> 2024-05-31 | B34: =I33*Monthly!C34/Monthly!C33 -> 101038.17 | C34: =J33*Monthly!D34/Monthly!D33 -> 63351.191 | D34: =SUM(B34:C34) -> 164389.36 | E34: =IF(Parameters!$B$4=0,FALSE(),MOD(32,Parameters!$B$4)=0) -> FALSE | F34: =ABS(D34*Parameters!$B$8-B34)+ABS(D34*Parameters!$B$9-C34) -> 0 | G34: =IF(E34,F34*Parameters!$B$3/10000,0) -> 0 | H34: =IF(ABS(Parameters!$B$5-1)>0.00000001,NA(),D34-G34) -> 164389.36 | I34: =IF(E34,H34*Parameters!$B$8,B34) -> 101038.17 | J34: =IF(E34,H34*Parameters!$B$9,C34) -> 63351.191 | K34: =MAX(Parameters!$B$2,H$2:H34) -> 164389.36 | L34: =H34/K34-1 -> 0 | M34: =H34/H33-1 -> 0.036583978 | N34: 164389.36 | O34: =H34-N34 -> 0
A35: =Monthly!A35 -> 2024-06-28 | B35: =I34*Monthly!C35/Monthly!C34 -> 100902.07 | C35: =J34*Monthly!D35/Monthly!D34 -> 57086.783 | D35: =SUM(B35:C35) -> 157988.85 | E35: =IF(Parameters!$B$4=0,FALSE(),MOD(33,Parameters!$B$4)=0) -> TRUE | F35: =ABS(D35*Parameters!$B$8-B35)+ABS(D35*Parameters!$B$9-C35) -> 12217.515 | G35: =IF(E35,F35*Parameters!$B$3/10000,0) -> 24.435029 | H35: =IF(ABS(Parameters!$B$5-1)>0.00000001,NA(),D35-G35) -> 157964.42 | I35: =IF(E35,H35*Parameters!$B$8,B35) -> 94778.65 | J35: =IF(E35,H35*Parameters!$B$9,C35) -> 63185.766 | K35: =MAX(Parameters!$B$2,H$2:H35) -> 164389.36 | L35: =H35/K35-1 -> -0.039083678 | M35: =H35/H34-1 -> -0.039083678 | N35: 157964.42 | O35: =H35-N35 -> 0
A36: =Monthly!A36 -> 2024-07-31 | B36: =I35*Monthly!C36/Monthly!C35 -> 99865.606 | C36: =J35*Monthly!D36/Monthly!D35 -> 67899.934 | D36: =SUM(B36:C36) -> 167765.54 | E36: =IF(Parameters!$B$4=0,FALSE(),MOD(34,Parameters!$B$4)=0) -> FALSE | F36: =ABS(D36*Parameters!$B$8-B36)+ABS(D36*Parameters!$B$9-C36) -> 0 | G36: =IF(E36,F36*Parameters!$B$3/10000,0) -> 0 | H36: =IF(ABS(Parameters!$B$5-1)>0.00000001,NA(),D36-G36) -> 167765.54 | I36: =IF(E36,H36*Parameters!$B$8,B36) -> 99865.606 | J36: =IF(E36,H36*Parameters!$B$9,C36) -> 67899.934 | K36: =MAX(Parameters!$B$2,H$2:H36) -> 167765.54 | L36: =H36/K36-1 -> 0 | M36: =H36/H35-1 -> 0.062046403 | N36: 167765.54 | O36: =H36-N36 -> 0
A37: =Monthly!A37 -> 2024-08-30 | B37: =I36*Monthly!C37/Monthly!C36 -> 101955.04 | C37: =J36*Monthly!D37/Monthly!D36 -> 60912.26 | D37: =SUM(B37:C37) -> 162867.3 | E37: =IF(Parameters!$B$4=0,FALSE(),MOD(35,Parameters!$B$4)=0) -> FALSE | F37: =ABS(D37*Parameters!$B$8-B37)+ABS(D37*Parameters!$B$9-C37) -> 0 | G37: =IF(E37,F37*Parameters!$B$3/10000,0) -> 0 | H37: =IF(ABS(Parameters!$B$5-1)>0.00000001,NA(),D37-G37) -> 162867.3 | I37: =IF(E37,H37*Parameters!$B$8,B37) -> 101955.04 | J37: =IF(E37,H37*Parameters!$B$9,C37) -> 60912.26 | K37: =MAX(Parameters!$B$2,H$2:H37) -> 167765.54 | L37: =H37/K37-1 -> -0.029196918 | M37: =H37/H36-1 -> -0.029196918 | N37: 162867.3 | O37: =H37-N37 -> 0
A38: =Monthly!A38 -> 2024-09-30 | B38: =I37*Monthly!C38/Monthly!C37 -> 107143.38 | C38: =J37*Monthly!D38/Monthly!D37 -> 67319.705 | D38: =SUM(B38:C38) -> 174463.09 | E38: =IF(Parameters!$B$4=0,FALSE(),MOD(36,Parameters!$B$4)=0) -> TRUE | F38: =ABS(D38*Parameters!$B$8-B38)+ABS(D38*Parameters!$B$9-C38) -> 4931.0607 | G38: =IF(E38,F38*Parameters!$B$3/10000,0) -> 9.8621214 | H38: =IF(ABS(Parameters!$B$5-1)>0.00000001,NA(),D38-G38) -> 174453.23 | I38: =IF(E38,H38*Parameters!$B$8,B38) -> 104671.94 | J38: =IF(E38,H38*Parameters!$B$9,C38) -> 69781.291 | K38: =MAX(Parameters!$B$2,H$2:H38) -> 174453.23 | L38: =H38/K38-1 -> 0 | M38: =H38/H37-1 -> 0.071137199 | N38: 174453.23 | O38: =H38-N38 -> 0
A39: =Monthly!A39 -> 2024-10-31 | B39: =I38*Monthly!C39/Monthly!C38 -> 109172.15 | C39: =J38*Monthly!D39/Monthly!D38 -> 76909.012 | D39: =SUM(B39:C39) -> 186081.16 | E39: =IF(Parameters!$B$4=0,FALSE(),MOD(37,Parameters!$B$4)=0) -> FALSE | F39: =ABS(D39*Parameters!$B$8-B39)+ABS(D39*Parameters!$B$9-C39) -> 0 | G39: =IF(E39,F39*Parameters!$B$3/10000,0) -> 0 | H39: =IF(ABS(Parameters!$B$5-1)>0.00000001,NA(),D39-G39) -> 186081.16 | I39: =IF(E39,H39*Parameters!$B$8,B39) -> 109172.15 | J39: =IF(E39,H39*Parameters!$B$9,C39) -> 76909.012 | K39: =MAX(Parameters!$B$2,H$2:H39) -> 186081.16 | L39: =H39/K39-1 -> 0 | M39: =H39/H38-1 -> 0.066653582 | N39: 186081.16 | O39: =H39-N39 -> 0
A40: =Monthly!A40 -> 2024-11-29 | B40: =I39*Monthly!C40/Monthly!C39 -> 105761.46 | C40: =J39*Monthly!D40/Monthly!D39 -> 101694.55 | D40: =SUM(B40:C40) -> 207456.01 | E40: =IF(Parameters!$B$4=0,FALSE(),MOD(38,Parameters!$B$4)=0) -> FALSE | F40: =ABS(D40*Parameters!$B$8-B40)+ABS(D40*Parameters!$B$9-C40) -> 0 | G40: =IF(E40,F40*Parameters!$B$3/10000,0) -> 0 | H40: =IF(ABS(Parameters!$B$5-1)>0.00000001,NA(),D40-G40) -> 207456.01 | I40: =IF(E40,H40*Parameters!$B$8,B40) -> 105761.46 | J40: =IF(E40,H40*Parameters!$B$9,C40) -> 101694.55 | K40: =MAX(Parameters!$B$2,H$2:H40) -> 207456.01 | L40: =H40/K40-1 -> 0 | M40: =H40/H39-1 -> 0.11486843 | N40: 207456.01 | O40: =H40-N40 -> 0
...

Sheet ExecutionLedger
A1: Symbol | B1: Signal UTC | C1: Execution UTC | D1: Adjusted units | E1: Adjusted open | F1: Notional | G1: Cost | H1: Cash after
A2: BTC-USD | B2: 2021-09-30T20:00:00+00:00 | C2: 2021-10-01T00:00:00+00:00 | D2: 0.95852876 | E2: 43816.742 | F2: 41999.607 | G2: 83.999215 | H2: 57916.393
A3: GLD | B3: 2021-09-30T20:00:00+00:00 | C3: 2021-10-01T13:30:00+00:00 | D3: 351.86455 | E3: 164.27 | F3: 57800.792 | G3: 115.60158 | H3: 0
A4: BTC-USD | B4: 2021-12-31T21:00:00+00:00 | C4: 2022-01-01T00:00:00+00:00 | D4: -0.068654223 | E4: 46311.746 | F4: -3179.497 | G4: 6.3589939 | H4: 3173.138
A5: GLD | B5: 2021-12-31T21:00:00+00:00 | C5: 2022-01-03T14:30:00+00:00 | D5: 16.490122 | E5: 168.86 | F5: 2784.5221 | G5: 5.5690441 | H5: 383.04687
A6: BTC-USD | B6: 2022-03-31T20:00:00+00:00 | C6: 2022-04-01T00:00:00+00:00 | D6: 0.0083918191 | E6: 45554.164 | F6: 382.2823 | G6: 0.76456461 | H6: 5.6843419e-14
A7: GLD | B7: 2022-03-31T20:00:00+00:00 | C7: 2022-04-01T13:30:00+00:00 | D7: -8.4121488 | E7: 179.55 | F7: -1510.4013 | G7: 3.0208027 | H7: 1507.3805
A8: BTC-USD | B8: 2022-06-30T20:00:00+00:00 | C8: 2022-07-01T00:00:00+00:00 | D8: 0.075899902 | E8: 19820.471 | F8: 1504.3718 | G8: 3.0087436 | H8: 2.2737368e-13
A9: GLD | B9: 2022-06-30T20:00:00+00:00 | C9: 2022-07-01T13:30:00+00:00 | D9: -75.426789 | E9: 167.14 | F9: -12606.833 | G9: 25.213667 | H9: 12581.62
A10: BTC-USD | B10: 2022-09-30T20:00:00+00:00 | C10: 2022-10-01T00:00:00+00:00 | D10: 0.5657809 | E10: 19431.105 | F10: 10993.748 | G10: 21.987497 | H10: 1565.884
A11: GLD | B11: 2022-09-30T20:00:00+00:00 | C11: 2022-10-03T13:30:00+00:00 | D11: 7.7981956 | E11: 155.44 | F11: 1212.1515 | G11: 2.4243031 | H11: 351.30814
A12: BTC-USD | B12: 2022-12-30T21:00:00+00:00 | C12: 2022-12-31T00:00:00+00:00 | D12: 0.021116226 | E12: 16603.674 | F12: 350.60693 | G12: 0.70121385 | H12: 0
A13: GLD | B13: 2022-12-30T21:00:00+00:00 | C13: 2023-01-03T14:30:00+00:00 | D13: -26.103003 | E13: 171.32001 | F13: -4471.9666 | G13: 8.9439332 | H13: 4463.0227
... A41: GLD | B41: 2026-06-30T20:00:00+00:00 | C41: 2026-07-01T13:30:00+00:00 | D41: 9.7786964 | E41: 371.20999 | F41: 3629.9498 | G41: 7.2598996 | H41: 1166.1975

Sheet EventWindows
A1: Event ID | B1: 事件 | C1: 来源日期 | D1: 对齐交易日 | E1: Symbol | F1: Window | G1: Return | H1: Benchmark | I1: Relative | J1: Strength | K1: Confidence | L1: Source IDs | M1: 说明 | N1: Window start UTC | O1: Window end UTC
A2: ev-1 | B2: 美联储加息75个基点，为1994年以来最大单次加息 | C2: 2022-06-15 | D2: 2022-06-15 | E2: GLD | F2: 1 | G2: 0.013050939 | H2: 0.014256557 | I2: -0.0012056172 | J2: 低 | K2: high | L2: src-4f517df5f22832, src-eefffabc38a184 | M2: 日线包含公告前交易，无法精确隔离盘中反应。 | N2: 2022-06-14T20:00:00+00:00 | O2: 2022-06-15T20:00:00+00:00
A3: ev-1 | B3: 美联储加息75个基点，为1994年以来最大单次加息 | C3: 2022-06-15 | D3: 2022-06-15 | E3: GLD | F3: 5 | G3: 0.016254316 | H3: 0.0057164943 | I3: 0.010537822 | J3: 低 | K3: high | L3: src-4f517df5f22832, src-eefffabc38a184 | M3: 日线包含公告前交易，无法精确隔离盘中反应。 | N3: 2022-06-14T20:00:00+00:00 | O3: 2022-06-22T20:00:00+00:00
A4: ev-1 | B4: 美联储加息75个基点，为1994年以来最大单次加息 | C4: 2022-06-15 | D4: 2022-06-15 | E4: GLD | F4: 20 | G4: -0.054814054 | H4: 0.015172084 | I4: -0.069986138 | J4: 低 | K4: high | L4: src-4f517df5f22832, src-eefffabc38a184 | M4: 日线包含公告前交易，无法精确隔离盘中反应。 | N4: 2022-06-14T20:00:00+00:00 | O4: 2022-07-14T20:00:00+00:00
A5: ev-4 | B5: 美联储9月加息75个基点至3%–3.25% | C5: 2022-09-21 | D5: 2022-09-21 | E5: GLD | F5: 1 | G5: 0.0046429737 | H5: -0.017443681 | I5: 0.022086655 | J5: 中 | K5: medium | L5: src-d39adf303e613c | M5: 来源只有日期，盘前/盘后时间不确定；使用当日或下一交易日近似。 | N5: 2022-09-20T20:00:00+00:00 | O5: 2022-09-21T20:00:00+00:00
A6: ev-4 | B6: 美联储9月加息75个基点至3%–3.25% | C6: 2022-09-21 | D6: 2022-09-21 | E6: GLD | F6: 5 | G6: -0.022764003 | H6: -0.053919533 | I6: 0.031155531 | J6: 中 | K6: medium | L6: src-d39adf303e613c | M6: 来源只有日期，盘前/盘后时间不确定；使用当日或下一交易日近似。 | N6: 2022-09-20T20:00:00+00:00 | O6: 2022-09-27T20:00:00+00:00
A7: ev-4 | B7: 美联储9月加息75个基点至3%–3.25% | C7: 2022-09-21 | D7: 2022-09-21 | E7: GLD | F7: 20 | G7: -0.0085123316 | H7: -0.033742063 | I7: 0.025229731 | J7: 中 | K7: medium | L7: src-d39adf303e613c | M7: 来源只有日期，盘前/盘后时间不确定；使用当日或下一交易日近似。 | N7: 2022-09-20T20:00:00+00:00 | O7: 2022-10-18T20:00:00+00:00
A8: ev-7 | B8: 黄金重挫、白银期货暴跌31.4%，沃什获提名缓解美联储独立性担忧 | C8: 2026-01-30 | D8: 2026-01-30 | E8: GLD | F8: 1 | G8: -0.10274245 | H8: -0.002982534 | I8: -0.099759919 | J8: 高 | K8: high | L8: src-52290fdbe0be60 | N8: 2026-01-29T21:00:00+00:00 | O8: 2026-01-30T21:00:00+00:00
A9: ev-7 | B9: 黄金重挫、白银期货暴跌31.4%，沃什获提名缓解美联储独立性担忧 | C9: 2026-01-30 | D9: 2026-01-30 | E9: GLD | F9: 5 | G9: -0.10893323 | H9: -0.023658553 | I9: -0.085274679 | J9: 高 | K9: high | L9: src-52290fdbe0be60 | N9: 2026-01-29T21:00:00+00:00 | O9: 2026-02-05T21:00:00+00:00
A10: ev-7 | B10: 黄金重挫、白银期货暴跌31.4%，沃什获提名缓解美联储独立性担忧 | C10: 2026-01-30 | D10: 2026-01-30 | E10: GLD | F10: 20 | G10: -0.024500895 | H10: -0.011598753 | I10: -0.012902142 | J10: 高 | K10: high | L10: src-52290fdbe0be60 | N10: 2026-01-29T21:00:00+00:00 | O10: 2026-02-27T21:00:00+00:00
A11: ev-9 | B11: 比特币一度跌破6.1万美元，单周跌近30%，表现远逊黄金 | C11: 2026-02-05 | D11: 2026-02-05 | E11: GLD | F11: 1 | G11: -0.026631708 | H11: -0.012489281 | I11: -0.014142427 | J11: 低 | K11: high | L11: src-6e0021d495f65b | N11: 2026-02-04T21:00:00+00:00 | O11: 2026-02-05T21:00:00+00:00
A12: ev-9 | B12: 比特币一度跌破6.1万美元，单周跌近30%，表现远逊黄金 | C12: 2026-02-05 | D12: 2026-02-05 | E12: GLD | F12: 5 | G12: 0.030090102 | H12: 0.0084087482 | I12: 0.021681354 | J12: 低 | K12: high | L12: src-6e0021d495f65b | N12: 2026-02-04T21:00:00+00:00 | O12: 2026-02-11T21:00:00+00:00
A13: ev-9 | B13: 比特币一度跌破6.1万美元，单周跌近30%，表现远逊黄金 | C13: 2026-02-05 | D13: 2026-02-05 | E13: GLD | F13: 20 | G13: 0.026785919 | H13: -0.0071117985 | I13: 0.033897717 | J13: 低 | K13: high | L13: src-6e0021d495f65b | N13: 2026-02-04T21:00:00+00:00 | O13: 2026-03-05T21:00:00+00:00
A14: ev-1 | B14: 美联储加息75个基点，为1994年以来最大单次加息 | C14: 2022-06-15 | D14: 2022-06-15 | E14: BTC-USD | F14: 1 | G14: 0.016483554 | H14: 0.014256557 | I14: 0.0022269975 | J14: 低 | K14: high | L14: src-4f517df5f22832, src-eefffabc38a184 | M14: 日线包含公告前交易，无法精确隔离盘中反应。 同期存在其他已收录事件，无法分离各自作用。 | N14: 2022-06-15T00:00:00+00:00 | O14: 2022-06-16T00:00:00+00:00
A15: ev-1 | B15: 美联储加息75个基点，为1994年以来最大单次加息 | C15: 2022-06-15 | D15: 2022-06-15 | E15: BTC-USD | F15: 5 | G15: -0.074460166 | H15: -0.017197513 | I15: -0.057262652 | J15: 低 | K15: high | L15: src-4f517df5f22832, src-eefffabc38a184 | M15: 日线包含公告前交易，无法精确隔离盘中反应。 同期存在其他已收录事件，无法分离各自作用。 | N15: 2022-06-15T00:00:00+00:00 | O15: 2022-06-20T00:00:00+00:00
A16: ev-1 | B16: 美联储加息75个基点，为1994年以来最大单次加息 | C16: 2022-06-15 | D16: 2022-06-15 | E16: BTC-USD | F16: 20 | G16: -0.088960673 | H16: 0.024117631 | I16: -0.1130783 | J16: 低 | K16: high | L16: src-4f517df5f22832, src-eefffabc38a184 | M16: 日线包含公告前交易，无法精确隔离盘中反应。 同期存在其他已收录事件，无法分离各自作用。 | N16: 2022-06-15T00:00:00+00:00 | O16: 2022-07-05T00:00:00+00:00
A17: ev-2 | B17: 比特币跌破2.3万美元，Celsius暂停提款加剧加密市场抛售 | C17: 2022-06-13 | D17: 2022-06-13 | E17: BTC-USD | F17: 1 | G17: -0.15974726 | H17: -0.037968202 | I17: -0.12177906 | J17: 高 | K17: high | L17: src-84d4aa2b0397b9 | M17: 日线包含公告前交易，无法精确隔离盘中反应。 同期存在其他已收录事件，无法分离各自作用。 | N17: 2022-06-13T00:00:00+00:00 | O17: 2022-06-14T00:00:00+00:00
A18: ev-2 | B18: 比特币跌破2.3万美元，Celsius暂停提款加剧加密市场抛售 | C18: 2022-06-13 | D18: 2022-06-13 | E18: BTC-USD | F18: 5 | G18: -0.23507262 | H18: -0.057361672 | I18: -0.17771095 | J18: 高 | K18: high | L18: src-84d4aa2b0397b9 | M18: 日线包含公告前交易，无法精确隔离盘中反应。 同期存在其他已收录事件，无法分离各自作用。 | N18: 2022-06-13T00:00:00+00:00 | O18: 2022-06-18T00:00:00+00:00
A19: ev-2 | B19: 比特币跌破2.3万美元，Celsius暂停提款加剧加密市场抛售 | C19: 2022-06-13 | D19: 2022-06-13 | E19: BTC-USD | F19: 20 | G19: -0.2810033 | H19: -0.017734953 | I19: -0.26326835 | J19: 高 | K19: high | L19: src-84d4aa2b0397b9 | M19: 日线包含公告前交易，无法精确隔离盘中反应。 同期存在其他已收录事件，无法分离各自作用。 | N19: 2022-06-13T00:00:00+00:00 | O19: 2022-07-03T00:00:00+00:00
A20: ev-3 | B20: Terra的LUNA跌至0美元、UST脱锚，比特币反弹至3万美元上方 | C20: 2022-05-13 | D20: 2022-05-13 | E20: BTC-USD | F20: 1 | G20: 0.0081022298 | H20: 0.023907973 | I20: -0.015805743 | J20: 低 | K20: high | L20: src-a50be069675b1c | M20: 日线包含公告前交易，无法精确隔离盘中反应。 | N20: 2022-05-13T00:00:00+00:00 | O20: 2022-05-14T00:00:00+00:00
A21: ev-3 | B21: Terra的LUNA跌至0美元、UST脱锚，比特币反弹至3万美元上方 | C21: 2022-05-13 | D21: 2022-05-13 | E21: BTC-USD | F21: 5 | G21: 0.047442758 | H21: 0.040730036 | I21: 0.0067127216 | J21: 低 | K21: high | L21: src-a50be069675b1c | M21: 日线包含公告前交易，无法精确隔离盘中反应。 | N21: 2022-05-13T00:00:00+00:00 | O21: 2022-05-18T00:00:00+00:00
A22: ev-3 | B22: Terra的LUNA跌至0美元、UST脱锚，比特币反弹至3万美元上方 | C22: 2022-05-13 | D22: 2022-05-13 | E22: BTC-USD | F22: 20 | G22: 0.025865276 | H22: 0.043966857 | I22: -0.018101581 | J22: 低 | K22: high | L22: src-a50be069675b1c | M22: 日线包含公告前交易，无法精确隔离盘中反应。 | N22: 2022-05-13T00:00:00+00:00 | O22: 2022-06-02T00:00:00+00:00
A23: ev-4 | B23: 美联储9月加息75个基点至3%–3.25% | C23: 2022-09-21 | D23: 2022-09-21 | E23: BTC-USD | F23: 1 | G23: -0.018177572 | H23: -0.017443681 | I23: -0.00073389058 | J23: 低 | K23: medium | L23: src-d39adf303e613c | M23: 来源只有日期，盘前/盘后时间不确定；使用当日或下一交易日近似。 | N23: 2022-09-21T00:00:00+00:00 | O23: 2022-09-22T00:00:00+00:00
A24: ev-4 | B24: 美联储9月加息75个基点至3%–3.25% | C24: 2022-09-21 | D24: 2022-09-21 | E24: BTC-USD | F24: 5 | G24: -0.0046949551 | H24: -0.042021257 | I24: 0.037326302 | J24: 低 | K24: medium | L24: src-d39adf303e613c | M24: 来源只有日期，盘前/盘后时间不确定；使用当日或下一交易日近似。 | N24: 2022-09-21T00:00:00+00:00 | O24: 2022-09-26T00:00:00+00:00
A25: ev-4 | B25: 美联储9月加息75个基点至3%–3.25% | C25: 2022-09-21 | D25: 2022-09-21 | E25: BTC-USD | F25: 20 | G25: 0.01327077 | H25: -0.062667441 | I25: 0.075938211 | J25: 低 | K25: medium | L25: src-d39adf303e613c | M25: 来源只有日期，盘前/盘后时间不确定；使用当日或下一交易日近似。 | N25: 2022-09-21T00:00:00+00:00 | O25: 2022-10-11T00:00:00+00:00
... A40: ev-10 | B40: 特朗普宣布美国“战略加密储备”将纳入比特币等五种资产 | C40: 2025-03-02 | D40: 2025-03-02 | E40: BTC-USD | F40: 20 | G40: -0.023115514 | H40: -0.047970988 | I40: 0.024855474 | J40: 中 | K40: high | L40: src-65b6657762695e, src-836ed4c0a4973f | M40: 日线包含公告前交易，无法精确隔离盘中反应。 | N40: 2025-03-02T00:00:00+00:00 | O40: 2025-03-22T00:00:00+00:00

Sheet Sources
A1: ID | B1: Title | C1: Original URL | D1: Retrieved UTC | E1: SHA-256 | F1: Status
A2: src-4f517df5f22832 | B2: Federal Reserve Board - Federal Reserve issues FOMC statement | C2: https://www.federalreserve.gov/newsevents/pressreleases/monetary20220615a.htm | D2: 2026-09-29T02:49:31.305620+00:00 | E2: 36b58bf8d97bd274b50c64087ea4e47d7e93ff4b69ff6df8e55cac2816fc4e62 | F2: retrieved
A3: src-d39adf303e613c | B3: Federal Reserve Board - Federal Reserve issues FOMC statement | C3: https://www.federalreserve.gov/newsevents/pressreleases/monetary20220921a.htm | D3: 2026-09-29T02:49:56.224494+00:00 | E3: 890e6f45d610a09ea9ac8e240fe189e100985f51e5779b0618e829784cf0840b | F3: retrieved
A4: src-a50be069675b1c | B4: Cryptocurrency luna crashes to $0 as UST falls from peg; bitcoin rises | C4: https://www.cnbc.com/2022/05/13/cryptocurrency-luna-crashes-to-0-as-ust-falls-from-peg-bitcoin-rises.html | D4: 2026-09-29T02:49:57.419007+00:00 | E4: 82672624eddec639dc2a784ad6670b600c7dfd2baec9cb51296acd3f4f0c1ee6 | F4: retrieved
A5: src-65b6657762695e | B5: Trump announces strategic crypto reserve including bitcoin, Solana, XRP and more | C5: https://www.cnbc.com/2025/03/02/trump-announces-strategic-crypto-reserve-including-bitcoin-solana-xrp-and-more.html | D5: 2026-09-29T02:50:22.632342+00:00 | E5: 0fadd2cde9419e6709176e779e0ba1a8a7ec444eb987f64b2d7c13fa5d5e849a | F5: retrieved
A6: src-1607273d2324e2 | B6: Bitcoin Blasts Past $31,000 as Optimism for BTC Spot ETF Surges - Decrypt | C6: https://decrypt.co/202840/bitcoin-31000-spot-btc-etf-optimism | D6: 2026-09-29T02:50:42.692862+00:00 | E6: ac43332d7809ca7ef3b42d6b609c4eab2250485b7527ff5713f9ee4b5dff651d | F6: retrieved
A7: src-b38ac08d0bba86 | B7: SPDR® Gold Shares (Ticker: GLD, New York Stock Exchange) | Charts, data and downloads | World Gold Trust Services | C7: https://www.spdrgoldshares.com/usa/gld/ | D7: 2026-09-29T02:50:43.093683+00:00 | E7: b81e6d2517df42d383c5172de04ea44ee4557bb986582a1b2401c901e59db446 | F7: retrieved
A8: src-6e0021d495f65b | B8: Bitcoin briefly breaks below $61,000 as sell-off intensifies | C8: https://www.cnbc.com/2026/02/05/bitcoin-price-today-70000-in-focus.html | D8: 2026-09-29T02:50:43.650350+00:00 | E8: 1e3b49a621f691aab4908f2a31b78e1f900ed931652ad67ff41a321643094839 | F8: retrieved
A9: src-c1c0f360de49ce | B9: SEC approves rule changes that pave the way for bitcoin ETFs | C9: https://www.cnbc.com/2024/01/10/sec-approves-rule-changes-that-pave-the-way-for-bitcoin-etfs.html | D9: 2026-09-29T02:51:05.147130+00:00 | E9: 0e817172b577027a6459beee16c4e7d10566b2efc4f9660d10e3e2052a26b0de | F9: retrieved
A10: src-cb000c43e683b8 | B10: Bitcoin price falls under $80,000. Here's why | C10: https://www.cnbc.com/2026/02/02/bitcoin-btc-price-today-cryptocurrency.html | D10: 2026-09-29T02:51:26.192826+00:00 | E10: bf74606b6fa77aa956ca1713091d41a61127cd08bc1fd0a373a87e6bd72e6552 | F10: retrieved
A11: src-836ed4c0a4973f | B11: What to know about Trump's 'crypto strategic reserve' plan : NPR | C11: https://www.npr.org/2025/03/04/g-s1-51748/trump-crypto-reserve-bitcoin-stockpile-ether | D11: 2026-09-29T02:51:26.732562+00:00 | E11: c24ed3b9bc2bf20d1939939ee364a236e4e295137d9e13484472985360b0561d | F11: retrieved
A12: src-52290fdbe0be60 | B12: Silver, gold sell off as precious metals markets nosedive | C12: https://www.cnbc.com/2026/01/30/silver-gold-fall-price-usd-dollar-fed-warsh-chair-trump-metals.html | D12: 2026-09-29T02:51:50.385231+00:00 | E12: 9079a70b490cca4058c19e8f9c28b76288da8e3dbe7eb53fe04ea88877044ea6 | F12: retrieved
... A19: prices-SPY-ba0266b147e1 | B19: SPY | C19: https://query1.finance.yahoo.com/v8/finance/chart/SPY?period1=1598227200&period2=1790726400&interval=1d&events=div%2Csplits&includeAdjustedClose=true | D19: 2026-09-29T02:33:25.620138+00:00 | E19: ba0266b147e1210651f9991e41f1ed135bc89c7cc3faa0088be1865d09d2bbb6 | F19: Yahoo split-adjusted OHLC; adj_close additionally reflects distributions

Sheet Macro
A1: Series | B1: Observation date | C1: Value | D1: Vintage use
A2: CPIAUCNS | B2: 2020-09-01 | C2: 260.28 | D2: 当前历史版本，仅用于事后分析
A3: CPIAUCNS | B3: 2020-10-01 | C3: 260.388 | D3: 当前历史版本，仅用于事后分析
A4: CPIAUCNS | B4: 2020-11-01 | C4: 260.229 | D4: 当前历史版本，仅用于事后分析
A5: CPIAUCNS | B5: 2020-12-01 | C5: 260.474 | D5: 当前历史版本，仅用于事后分析
A6: CPIAUCNS | B6: 2021-01-01 | C6: 261.582 | D6: 当前历史版本，仅用于事后分析
A7: CPIAUCNS | B7: 2021-02-01 | C7: 263.014 | D7: 当前历史版本，仅用于事后分析
A8: CPIAUCNS | B8: 2021-03-01 | C8: 264.877 | D8: 当前历史版本，仅用于事后分析
A9: CPIAUCNS | B9: 2021-04-01 | C9: 267.054 | D9: 当前历史版本，仅用于事后分析
A10: CPIAUCNS | B10: 2021-05-01 | C10: 269.195 | D10: 当前历史版本，仅用于事后分析
A11: CPIAUCNS | B11: 2021-06-01 | C11: 271.696 | D11: 当前历史版本，仅用于事后分析
A12: CPIAUCNS | B12: 2021-07-01 | C12: 273.003 | D12: 当前历史版本，仅用于事后分析
A13: CPIAUCNS | B13: 2021-08-01 | C13: 273.567 | D13: 当前历史版本，仅用于事后分析
... A1595: DGS3MO | B1595: 2026-09-25 | C1595: 4.24 | D1595: 当前历史版本，仅用于事后分析

Sheet Coverage
A1: 检查项 | B1: 状态 | C1: 依据 / 缺口
A2: 研究要求覆盖 | B2: 通过 | C2: 覆盖检查与事实核验分别执行；相关不代表因果

Sheet Associations
A1: 异动日期 | B1: 资产 | C1: 事件 ID | D1: 滞后日线数 | E1: 关联类型 | F1: 依据 | G1: 来源 ID
A2: 2026-01-30 | B2: GLD | C2: ev-7 | D2: 0 | E2: same_session_candidate | F2: 来源支持的事件公开后第 0 根日线出现变化；同标的与时间先后支持候选关联，未证明该事件触发行情。 | G2: src-52290fdbe0be60
A3: 2022-06-13 | B3: BTC-USD | C3: ev-2 | D3: 0 | E3: same_session_candidate | F3: 来源支持的事件公开后第 0 根日线出现变化；同标的与时间先后支持候选关联，未证明该事件触发行情。 | G3: src-84d4aa2b0397b9
A4: 2023-10-23 | B4: BTC-USD | C4: ev-5 | D4: 0 | E4: same_session_candidate | F4: 来源支持的事件公开后第 0 根日线出现变化；同标的与时间先后支持候选关联，未证明该事件触发行情。 | G4: src-1607273d2324e2
A5: 2025-03-02 | B5: BTC-USD | C5: ev-10 | D5: 0 | E5: same_session_candidate | F5: 来源支持的事件公开后第 0 根日线出现变化；同标的与时间先后支持候选关联，未证明该事件触发行情。 | G5: src-65b6657762695e, src-836ed4c0a4973f
A6: 2026-02-05 | B6: BTC-USD | C6: ev-9 | D6: 0 | E6: same_session_candidate | F6: 来源支持的事件公开后第 0 根日线出现变化；同标的与时间先后支持候选关联，未证明该事件触发行情。 | G6: src-6e0021d495f65b
A7: 2026-02-05 | B7: BTC-USD | C7: ev-8 | D7: 3 | E7: delayed_candidate | F7: 来源支持的事件公开后第 3 根日线出现变化；同标的与时间先后支持候选关联，未证明该事件触发行情。 | G7: src-cb000c43e683b8

Sheet Sensitivity
A1: 情景 | B1: 开始 | C1: 结束 | D1: 权重 | E1: 成本 bps | F1: 再平衡月数 | G1: 年化收益 | H1: 最大回撤 | I1: 年化波动 | J1: 累计费用 USD | K1: 数据 ID
A2: 原始配置 | B2: 2021-09-30 | C2: 2026-08-31 | D2: [0.6, 0.4] | E2: 20 | F2: 3 | G2: 0.21656505 | H2: -0.36741482 | I2: 0.24855433 | J2: 746.68906 | K2: prices-GLD-1a8f833cf4e3, prices-BTC-USD-f3226c91d62b
A3: 成本 0 bps | B3: 2021-09-30 | C3: 2026-08-31 | D3: [0.6, 0.4] | E3: 0 | F3: 3 | G3: 0.21821158 | H3: -0.3662156 | I3: 0.2487817 | J3: 0 | K3: prices-GLD-1a8f833cf4e3, prices-BTC-USD-f3226c91d62b
A4: 成本 10 bps | B4: 2021-09-30 | C4: 2026-08-31 | D4: [0.6, 0.4] | E4: 10 | F4: 3 | G4: 0.21742793 | H4: -0.36676953 | I4: 0.24866403 | J4: 372.59429 | K4: prices-GLD-1a8f833cf4e3, prices-BTC-USD-f3226c91d62b
A5: 成本 25 bps | B5: 2021-09-30 | C5: 2026-08-31 | D5: [0.6, 0.4] | E5: 25 | F5: 3 | G5: 0.21613182 | H5: -0.36773634 | I5: 0.24849989 | J5: 934.28206 | K5: prices-GLD-1a8f833cf4e3, prices-BTC-USD-f3226c91d62b
A6: 成本 50 bps | B6: 2021-09-30 | C6: 2026-08-31 | D6: [0.6, 0.4] | E6: 50 | F6: 3 | G6: 0.2139482 | H6: -0.3693328 | I6: 0.24823184 | J6: 1877.4351 | K6: prices-GLD-1a8f833cf4e3, prices-BTC-USD-f3226c91d62b
A7: 买入持有 | B7: 2021-09-30 | C7: 2026-08-31 | D7: [0.6, 0.4] | E7: 20 | F7: 0 | G7: 0.17190997 | H7: -0.37313448 | I7: 0.24898062 | J7: 199.6008 | K7: prices-GLD-1a8f833cf4e3, prices-BTC-USD-f3226c91d62b
A8: 每 1 月再平衡 | B8: 2021-09-30 | C8: 2026-08-31 | D8: [0.6, 0.4] | E8: 20 | F8: 1 | G8: 0.21616116 | H8: -0.36304824 | I8: 0.25416372 | J8: 1133.0894 | K8: prices-GLD-1a8f833cf4e3, prices-BTC-USD-f3226c91d62b
A9: 每 12 月再平衡 | B9: 2021-09-30 | C9: 2026-08-31 | D9: [0.6, 0.4] | E9: 20 | F9: 12 | G9: 0.18746279 | H9: -0.37398556 | I9: 0.25631365 | J9: 364.07445 | K9: prices-GLD-1a8f833cf4e3, prices-BTC-USD-f3226c91d62b
A10: GLD 20% | B10: 2021-09-30 | C10: 2026-08-31 | D10: [0.2, 0.8] | E10: 20 | F10: 3 | G10: 0.17376776 | H10: -0.6280235 | I10: 0.44402111 | J10: 573.97086 | K10: prices-GLD-1a8f833cf4e3, prices-BTC-USD-f3226c91d62b
A11: GLD 50% | B11: 2021-09-30 | C11: 2026-08-31 | D11: [0.5, 0.5] | E11: 20 | F11: 3 | G11: 0.21191236 | H11: -0.44008001 | I11: 0.29152264 | J11: 775.67039 | K11: prices-GLD-1a8f833cf4e3, prices-BTC-USD-f3226c91d62b
A12: GLD 80% | B12: 2021-09-30 | C12: 2026-08-31 | D12: [0.8, 0.19999999999999996] | E12: 20 | F12: 3 | G12: 0.21575992 | H12: -0.22477053 | I12: 0.18379886 | J12: 554.10615 | K12: prices-GLD-1a8f833cf4e3, prices-BTC-USD-f3226c91d62b
A13: 前半区间 | B13: 2021-09-30 | C13: 2024-03-28 | D13: [0.6, 0.4] | E13: 20 | F13: 3 | G13: 0.1886767 | H13: -0.36741482 | I13: 0.2874506 | J13: 356.99557 | K13: prices-GLD-1a8f833cf4e3, prices-BTC-USD-f3226c91d62b
A14: 后半区间 | B14: 2024-03-28 | C14: 2026-08-31 | D14: [0.6, 0.4] | E14: 20 | F14: 3 | G14: 0.23618483 | H14: -0.1923553 | I14: 0.20758778 | J14: 405.62694 | K14: prices-GLD-1a8f833cf4e3, prices-BTC-USD-f3226c91d62b
A17: 固定网格逐项改变一个参数；全部使用下一可交易开盘执行口径。分段结果为历史稳健性检查，不是样本外检验；不同期限比较应看年化及风险，不以全样本最优结果推荐配置。Excel 中该表为快照，不随蓝色输入格重算。
